Workbook

Sheet Survey
A1: Employee Experience Survey -- Item Bank
A2: Each item rated twice: Promise Score (1-10) = 'To what extent was this promised/expected?' | Experience Score (1-10) = 'To what extent do you experience this today?'
A4: Dimension | B4: Item # | C4: Measure | D4: Promise Question | E4: Experience Question | F4: Weight
A5: Job Fit | B5: 1 | C5: Role Clarity | D5: To what extent was 'Role Clarity' promised, communicated, or expected by the organization? | E5: To what extent do you actually experience 'Role Clarity' in your work today? | F5: 0.2
A6: Job Fit | B6: 2 | C6: Skill Utilization | D6: To what extent was 'Skill Utilization' promised, communicated, or expected by the organization? | E6: To what extent do you actually experience 'Skill Utilization' in your work today? | F6: 0.2
A7: Job Fit | B7: 3 | C7: Career Growth Alignment | D7: To what extent was 'Career Growth Alignment' promised, communicated, or expected by the organization? | E7: To what extent do you actually experience 'Career Growth Alignment' in your work today? | F7: 0.2
A8: Job Fit | B8: 4 | C8: Workload Appropriateness | D8: To what extent was 'Workload Appropriateness' promised, communicated, or expected by the organization? | E8: To what extent do you actually experience 'Workload Appropriateness' in your work today? | F8: 0.2
A9: Job Fit | B9: 5 | C9: Meaningfulness of Work | D9: To what extent was 'Meaningfulness of Work' promised, communicated, or expected by the organization? | E9: To what extent do you actually experience 'Meaningfulness of Work' in your work today? | F9: 0.2
A11: Manager Effectiveness | B11: 6 | C11: Coaching Quality | D11: To what extent was 'Coaching Quality' promised, communicated, or expected by the organization? | E11: To what extent do you actually experience 'Coaching Quality' in your work today? | F11: 0.2
A12: Manager Effectiveness | B12: 7 | C12: Feedback Quality | D12: To what extent was 'Feedback Quality' promised, communicated, or expected by the organization? | E12: To what extent do you actually experience 'Feedback Quality' in your work today? | F12: 0.2
A13: Manager Effectiveness | B13: 8 | C13: Fairness | D13: To what extent was 'Fairness' promised, communicated, or expected by the organization? | E13: To what extent do you actually experience 'Fairness' in your work today? | F13: 0.2
A14: Manager Effectiveness | B14: 9 | C14: Communication | D14: To what extent was 'Communication' promised, communicated, or expected by the organization? | E14: To what extent do you actually experience 'Communication' in your work today? | F14: 0.2
A15: Manager Effectiveness | B15: 10 | C15: Trust | D15: To what extent was 'Trust' promised, communicated, or expected by the organization? | E15: To what extent do you actually experience 'Trust' in your work today? | F15: 0.2
A17: Team Collaboration | B17: 11 | C17: Cooperation | D17: To what extent was 'Cooperation' promised, communicated, or expected by the organization? | E17: To what extent do you actually experience 'Cooperation' in your work today? | F17: 0.15
A18: Team Collaboration | B18: 12 | C18: Psychological Safety | D18: To what extent was 'Psychological Safety' promised, communicated, or expected by the organization? | E18: To what extent do you actually experience 'Psychological Safety' in your work today? | F18: 0.15
... A39: Rewards & Growth | B39: 30 | C39: Career Progression | D39: To what extent was 'Career Progression' promised, communicated, or expected by the organization? | E39: To what extent do you actually experience 'Career Progression' in your work today? | F39: 0.15
A42: Scale: 1 = 'Not at all' | 10 = 'Completely/To a great extent'
A43: Dimensions: 6 dimensions x 5 items = 30 items total | Weights: Job Fit(20%), Manager(20%), Team(15%), Culture(15%), Innovation(15%), Rewards(15%)

Sheet Raw Data
A1: Raw Survey Data -- Respondent Scores
A3: RespID | B3: Department | C3: Location | D3: Business Unit | E3: Manager | F3: P01 | G3: E01 | H3: P02 | I3: E02 | J3: P03 | K3: E03 | L3: P04 | M3: E04 | N3: P05 | O3: E05 | P3: P06 | Q3: E06 | R3: P07 | S3: E07 | T3: P08 | U3: E08 | V3: P09 | W3: E09 | X3: P10 | Y3: E10 | Z3: P11 | AA3: E11 | AB3: P12 | AC3: E12 | AD3: P13 | AE3: E13 | AF3: P14 | AG3: E14 | AH3: P15 | AI3: E15 | AJ3: P16 | AK3: E16 | AL3: P17 | AM3: E17 | AN3: P18 | AO3: E18 | AP3: P19 | AQ3: E19 | AR3: P20 | AS3: E20 | AT3: P21 | AU3: E21 | AV3: P22 | AW3: E22 | AX3: P23 | AY3: E23 | AZ3: P24 | BA3: E24 | BB3: P25 | BC3: E25 | BD3: P26 | BE3: E26 | BF3: P27 | BG3: E27 | BH3: P28 | BI3: E28 | BJ3: P29 | BK3: E29 | BL3: P30 | BM3: E30
A4: R001 | B4: Operations | C4: New York | D4: Core Product | E4: R. Kim | F4: 8 | G4: 7 | H4: 8 | I4: 4 | J4: 8 | K4: 6 | L4: 7 | M4: 5 | N4: 7 | O4: 5 | P4: 8 | Q4: 10 | R4: 9 | S4: 8 | T4: 9 | U4: 9 | V4: 7 | W4: 8 | X4: 8 | Y4: 7 | Z4: 9 | AA4: 9 | AB4: 7 | AC4: 8 | AD4: 7 | AE4: 7 | AF4: 6 | AG4: 4 | AH4: 9 | AI4: 4 | AJ4: 6 | AK4: 6 | AL4: 7 | AM4: 7 | AN4: 8 | AO4: 5 | AP4: 7 | AQ4: 5 | AR4: 8 | AS4: 9 | AT4: 8 | AU4: 7 | AV4: 10 | AW4: 7 | AX4: 7 | AY4: 6 | AZ4: 6 | BA4: 4 | BB4: 5 | BC4: 6 | BD4: 8 | BE4: 6 | BF4: 6 | BG4: 4 | BH4: 7 | BI4: 4 | BJ4: 9 | BK4: 7 | BL4: 8 | BM4: 4
A5: R002 | B5: Operations | C5: Sydney | D5: Core Product | E5: J. Brown | F5: 5 | G5: 10 | H5: 9 | I5: 3 | J5: 9 | K5: 5 | L5: 7 | M5: 7 | N5: 10 | O5: 6 | P5: 10 | Q5: 6 | R5: 9 | S5: 8 | T5: 7 | U5: 6 | V5: 10 | W5: 10 | X5: 9 | Y5: 5 | Z5: 8 | AA5: 7 | AB5: 8 | AC5: 6 | AD5: 7 | AE5: 6 | AF5: 9 | AG5: 3 | AH5: 9 | AI5: 8 | AJ5: 9 | AK5: 7 | AL5: 10 | AM5: 5 | AN5: 7 | AO5: 3 | AP5: 8 | AQ5: 4 | AR5: 7 | AS5: 6 | AT5: 9 | AU5: 6 | AV5: 10 | AW5: 6 | AX5: 8 | AY5: 6 | AZ5: 6 | BA5: 5 | BB5: 5 | BC5: 5 | BD5: 7 | BE5: 4 | BF5: 8 | BG5: 5 | BH5: 7 | BI5: 6 | BJ5: 10 | BK5: 6 | BL5: 10 | BM5: 6
A6: R003 | B6: Engineering | C6: London | D6: Growth | E6: L. Williams | F6: 7 | G6: 6 | H6: 5 | I6: 7 | J6: 9 | K6: 3 | L6: 9 | M6: 1 | N6: 8 | O6: 8 | P6: 8 | Q6: 7 | R6: 9 | S6: 6 | T6: 7 | U6: 7 | V6: 10 | W6: 6 | X6: 9 | Y6: 8 | Z6: 6 | AA6: 6 | AB6: 9 | AC6: 7 | AD6: 8 | AE6: 6 | AF6: 8 | AG6: 7 | AH6: 7 | AI6: 6 | AJ6: 9 | AK6: 5 | AL6: 7 | AM6: 4 | AN6: 6 | AO6: 5 | AP6: 8 | AQ6: 4 | AR6: 8 | AS6: 4 | AT6: 8 | AU6: 5 | AV6: 10 | AW6: 5 | AX6: 8 | AY6: 7 | AZ6: 9 | BA6: 3 | BB6: 9 | BC6: 8 | BD6: 6 | BE6: 2 | BF6: 10 | BG6: 5 | BH6: 7 | BI6: 1 | BJ6: 8 | BK6: 6 | BL6: 8 | BM6: 7
A7: R004 | B7: Marketing | C7: Tokyo | D7: Corporate | E7: R. Kim | F7: 10 | G7: 5 | H7: 9 | I7: 3 | J7: 9 | K7: 6 | L7: 7 | M7: 4 | N7: 10 | O7: 5 | P7: 9 | Q7: 7 | R7: 8 | S7: 7 | T7: 10 | U7: 1 | V7: 8 | W7: 4 | X7: 6 | Y7: 5 | Z7: 7 | AA7: 3 | AB7: 9 | AC7: 9 | AD7: 7 | AE7: 7 | AF7: 8 | AG7: 5 | AH7: 7 | AI7: 5 | AJ7: 10 | AK7: 1 | AL7: 9 | AM7: 9 | AN7: 9 | AO7: 2 | AP7: 7 | AQ7: 4 | AR7: 10 | AS7: 7 | AT7: 6 | AU7: 5 | AV7: 7 | AW7: 6 | AX7: 7 | AY7: 8 | AZ7: 9 | BA7: 6 | BB7: 8 | BC7: 4 | BD7: 10 | BE7: 8 | BF7: 9 | BG7: 6 | BH7: 9 | BI7: 2 | BJ7: 8 | BK7: 4 | BL7: 10 | BM7: 4
A8: R005 | B8: Operations | C8: New York | D8: Enterprise | E8: R. Kim | F8: 7 | G8: 5 | H8: 7 | I8: 6 | J8: 6 | K8: 8 | L8: 7 | M8: 6 | N8: 8 | O8: 7 | P8: 7 | Q8: 6 | R8: 8 | S8: 5 | T8: 10 | U8: 6 | V8: 8 | W8: 9 | X8: 10 | Y8: 9 | Z8: 7 | AA8: 9 | AB8: 10 | AC8: 8 | AD8: 8 | AE8: 5 | AF8: 6 | AG8: 5 | AH8: 7 | AI8: 7 | AJ8: 10 | AK8: 3 | AL8: 8 | AM8: 4 | AN8: 8 | AO8: 4 | AP8: 8 | AQ8: 5 | AR8: 7 | AS8: 6 | AT8: 7 | AU8: 8 | AV8: 9 | AW8: 2 | AX8: 9 | AY8: 5 | AZ8: 8 | BA8: 4 | BB8: 8 | BC8: 4 | BD8: 7 | BE8: 5 | BF8: 8 | BG8: 4 | BH8: 8 | BI8: 5 | BJ8: 8 | BK8: 6 | BL8: 7 | BM8: 6
A9: R006 | B9: Engineering | C9: London | D9: Corporate | E9: J. Brown | F9: 9 | G9: 5 | H9: 9 | I9: 4 | J9: 9 | K9: 6 | L9: 10 | M9: 3 | N9: 8 | O9: 4 | P9: 8 | Q9: 8 | R9: 9 | S9: 7 | T9: 8 | U9: 7 | V9: 10 | W9: 3 | X9: 8 | Y9: 6 | Z9: 8 | AA9: 8 | AB9: 7 | AC9: 7 | AD9: 8 | AE9: 5 | AF9: 8 | AG9: 6 | AH9: 9 | AI9: 7 | AJ9: 7 | AK9: 7 | AL9: 7 | AM9: 3 | AN9: 8 | AO9: 6 | AP9: 9 | AQ9: 7 | AR9: 8 | AS9: 8 | AT9: 8 | AU9: 7 | AV9: 9 | AW9: 7 | AX9: 8 | AY9: 6 | AZ9: 6 | BA9: 2 | BB9: 7 | BC9: 5 | BD9: 8 | BE9: 4 | BF9: 9 | BG9: 3 | BH9: 10 | BI9: 5 | BJ9: 7 | BK9: 6 | BL9: 7 | BM9: 8
A10: R007 | B10: Engineering | C10: Sydney | D10: Enterprise | E10: K. Taylor | F10: 7 | G10: 5 | H10: 9 | I10: 6 | J10: 6 | K10: 6 | L10: 8 | M10: 5 | N10: 8 | O10: 6 | P10: 8 | Q10: 8 | R10: 8 | S10: 7 | T10: 9 | U10: 8 | V10: 7 | W10: 9 | X10: 8 | Y10: 7 | Z10: 9 | AA10: 8 | AB10: 8 | AC10: 4 | AD10: 5 | AE10: 7 | AF10: 8 | AG10: 9 | AH10: 6 | AI10: 6 | AJ10: 7 | AK10: 7 | AL10: 8 | AM10: 4 | AN10: 8 | AO10: 6 | AP10: 6 | AQ10: 5 | AR10: 8 | AS10: 7 | AT10: 9 | AU10: 5 | AV10: 8 | AW10: 6 | AX10: 8 | AY10: 6 | AZ10: 7 | BA10: 10 | BB10: 7 | BC10: 5 | BD10: 6 | BE10: 5 | BF10: 7 | BG10: 5 | BH10: 10 | BI10: 6 | BJ10: 8 | BK10: 3 | BL10: 8 | BM10: 5
A11: R008 | B11: Finance | C11: Tokyo | D11: Core Product | E11: L. Williams | F11: 9 | G11: 8 | H11: 8 | I11: 5 | J11: 7 | K11: 7 | L11: 9 | M11: 6 | N11: 6 | O11: 5 | P11: 8 | Q11: 8 | R11: 9 | S11: 7 | T11: 9 | U11: 7 | V11: 8 | W11: 8 | X11: 8 | Y11: 5 | Z11: 9 | AA11: 5 | AB11: 6 | AC11: 4 | AD11: 6 | AE11: 6 | AF11: 8 | AG11: 6 | AH11: 7 | AI11: 9 | AJ11: 8 | AK11: 6 | AL11: 7 | AM11: 2 | AN11: 10 | AO11: 3 | AP11: 8 | AQ11: 7 | AR11: 10 | AS11: 5 | AT11: 10 | AU11: 4 | AV11: 7 | AW11: 6 | AX11: 6 | AY11: 6 | AZ11: 8 | BA11: 7 | BB11: 7 | BC11: 6 | BD11: 7 | BE11: 7 | BF11: 7 | BG11: 7 | BH11: 10 | BI11: 4 | BJ11: 7 | BK11: 5 | BL11: 9 | BM11: 5
A12: R009 | B12: Engineering | C12: Berlin | D12: Corporate | E12: J. Brown | F12: 9 | G12: 7 | H12: 7 | I12: 6 | J12: 8 | K12: 7 | L12: 9 | M12: 3 | N12: 9 | O12: 8 | P12: 10 | Q12: 9 | R12: 8 | S12: 7 | T12: 6 | U12: 7 | V12: 8 | W12: 10 | X12: 8 | Y12: 9 | Z12: 9 | AA12: 6 | AB12: 8 | AC12: 6 | AD12: 5 | AE12: 8 | AF12: 8 | AG12: 5 | AH12: 4 | AI12: 4 | AJ12: 9 | AK12: 7 | AL12: 7 | AM12: 5 | AN12: 8 | AO12: 6 | AP12: 7 | AQ12: 5 | AR12: 10 | AS12: 6 | AT12: 8 | AU12: 4 | AV12: 9 | AW12: 1 | AX12: 9 | AY12: 6 | AZ12: 9 | BA12: 3 | BB12: 6 | BC12: 5 | BD12: 7 | BE12: 6 | BF12: 5 | BG12: 6 | BH12: 7 | BI12: 3 | BJ12: 9 | BK12: 2 | BL12: 7 | BM12: 8
A13: R010 | B13: Finance | C13: New York | D13: Core Product | E13: L. Williams | F13: 6 | G13: 4 | H13: 8 | I13: 5 | J13: 6 | K13: 4 | L13: 9 | M13: 2 | N13: 7 | O13: 7 | P13: 7 | Q13: 8 | R13: 9 | S13: 8 | T13: 8 | U13: 5 | V13: 8 | W13: 9 | X13: 7 | Y13: 4 | Z13: 7 | AA13: 8 | AB13: 10 | AC13: 5 | AD13: 9 | AE13: 6 | AF13: 6 | AG13: 10 | AH13: 8 | AI13: 7 | AJ13: 10 | AK13: 2 | AL13: 10 | AM13: 6 | AN13: 10 | AO13: 5 | AP13: 9 | AQ13: 2 | AR13: 8 | AS13: 9 | AT13: 8 | AU13: 7 | AV13: 8 | AW13: 3 | AX13: 10 | AY13: 1 | AZ13: 6 | BA13: 4 | BB13: 7 | BC13: 8 | BD13: 9 | BE13: 7 | BF13: 6 | BG13: 4 | BH13: 8 | BI13: 8 | BJ13: 9 | BK13: 2 | BL13: 10 | BM13: 8
A14: R011 | B14: Marketing | C14: Sydney | D14: Enterprise | E14: A. Patel | F14: 8 | G14: 6 | H14: 6 | I14: 7 | J14: 6 | K14: 5 | L14: 10 | M14: 3 | N14: 8 | O14: 7 | P14: 9 | Q14: 6 | R14: 10 | S14: 9 | T14: 8 | U14: 7 | V14: 9 | W14: 8 | X14: 8 | Y14: 3 | Z14: 7 | AA14: 6 | AB14: 9 | AC14: 7 | AD14: 8 | AE14: 6 | AF14: 5 | AG14: 8 | AH14: 9 | AI14: 8 | AJ14: 9 | AK14: 5 | AL14: 8 | AM14: 6 | AN14: 7 | AO14: 6 | AP14: 8 | AQ14: 5 | AR14: 8 | AS14: 6 | AT14: 10 | AU14: 7 | AV14: 8 | AW14: 9 | AX14: 9 | AY14: 1 | AZ14: 5 | BA14: 5 | BB14: 8 | BC14: 5 | BD14: 10 | BE14: 1 | BF14: 9 | BG14: 6 | BH14: 9 | BI14: 6 | BJ14: 7 | BK14: 4 | BL14: 7 | BM14: 3
A15: R012 | B15: Operations | C15: Berlin | D15: Enterprise | E15: K. Taylor | F15: 8 | G15: 6 | H15: 9 | I15: 5 | J15: 7 | K15: 5 | L15: 8 | M15: 7 | N15: 7 | O15: 5 | P15: 7 | Q15: 8 | R15: 7 | S15: 6 | T15: 9 | U15: 8 | V15: 6 | W15: 5 | X15: 9 | Y15: 5 | Z15: 6 | AA15: 8 | AB15: 7 | AC15: 7 | AD15: 7 | AE15: 5 | AF15: 9 | AG15: 7 | AH15: 7 | AI15: 7 | AJ15: 9 | AK15: 5 | AL15: 6 | AM15: 7 | AN15: 6 | AO15: 7 | AP15: 8 | AQ15: 7 | AR15: 7 | AS15: 5 | AT15: 8 | AU15: 4 | AV15: 8 | AW15: 6 | AX15: 6 | AY15: 6 | AZ15: 6 | BA15: 4 | BB15: 6 | BC15: 4 | BD15: 9 | BE15: 5 | BF15: 9 | BG15: 4 | BH15: 9 | BI15: 7 | BJ15: 8 | BK15: 1 | BL15: 7 | BM15: 5
... A53: R050 | B53: Human Resources | C53: Berlin | D53: Growth | E53: K. Taylor | F53: 7 | G53: 7 | H53: 9 | I53: 6 | J53: 8 | K53: 8 | L53: 7 | M53: 6 | N53: 7 | O53: 7 | P53: 7 | Q53: 4 | R53: 7 | S53: 9 | T53: 7 | U53: 5 | V53: 8 | W53: 9 | X53: 8 | Y53: 6 | Z53: 8 | AA53: 8 | AB53: 8 | AC53: 5 | AD53: 8 | AE53: 5 | AF53: 7 | AG53: 9 | AH53: 6 | AI53: 6 | AJ53: 6 | AK53: 2 | AL53: 8 | AM53: 4 | AN53: 7 | AO53: 5 | AP53: 8 | AQ53: 8 | AR53: 6 | AS53: 6 | AT53: 6 | AU53: 4 | AV53: 7 | AW53: 6 | AX53: 8 | AY53: 4 | AZ53: 5 | BA53: 5 | BB53: 6 | BC53: 6 | BD53: 9 | BE53: 9 | BF53: 8 | BG53: 5 | BH53: 8 | BI53: 7 | BJ53: 10 | BK53: 5 | BL53: 7 | BM53: 10

Sheet Scoring Engine
A1: Scoring Engine -- Dimension & Overall Calculations
A2: All calculations use native Excel formulas. Extend row references as you add respondents.
A4: Dimension | B4: Avg Promise | C4: Avg Experience | D4: Gap | E4: Health Score (0-100) | F4: Classification | G4: Weight
A5: Job Fit | B5: =AVERAGE('Raw Data'!F4:F53,'Raw Data'!H4:H53,'Raw Data'!J4:J53,'Raw Data'!L4:L53,'Raw Data'!N4:N53) | C5: =AVERAGE('Raw Data'!G4:G53,'Raw Data'!I4:I53,'Raw Data'!K4:K53,'Raw Data'!M4:M53,'Raw Data'!O4:O53) | D5: =B5-C5 | E5: =MAX(0,MIN(100,100-D5*20)) | F5: =IF(D5<=1,"Healthy",IF(D5<=2,"Watch",IF(D5<=3,"Concern","High Risk"))) | G5: 0.2
A6: Manager Effectiveness | B6: =AVERAGE('Raw Data'!P4:P53,'Raw Data'!R4:R53,'Raw Data'!T4:T53,'Raw Data'!V4:V53,'Raw Data'!X4:X53) | C6: =AVERAGE('Raw Data'!Q4:Q53,'Raw Data'!S4:S53,'Raw Data'!U4:U53,'Raw Data'!W4:W53,'Raw Data'!Y4:Y53) | D6: =B6-C6 | E6: =MAX(0,MIN(100,100-D6*20)) | F6: =IF(D6<=1,"Healthy",IF(D6<=2,"Watch",IF(D6<=3,"Concern","High Risk"))) | G6: 0.2
A7: Team Collaboration | B7: =AVERAGE('Raw Data'!Z4:Z53,'Raw Data'!AB4:AB53,'Raw Data'!AD4:AD53,'Raw Data'!AF4:AF53,'Raw Data'!AH4:AH53) | C7: =AVERAGE('Raw Data'!AA4:AA53,'Raw Data'!AC4:AC53,'Raw Data'!AE4:AE53,'Raw Data'!AG4:AG53,'Raw Data'!AI4:AI53) | D7: =B7-C7 | E7: =MAX(0,MIN(100,100-D7*20)) | F7: =IF(D7<=1,"Healthy",IF(D7<=2,"Watch",IF(D7<=3,"Concern","High Risk"))) | G7: 0.15
A8: Workplace Culture | B8: =AVERAGE('Raw Data'!AJ4:AJ53,'Raw Data'!AL4:AL53,'Raw Data'!AN4:AN53,'Raw Data'!AP4:AP53,'Raw Data'!AR4:AR53) | C8: =AVERAGE('Raw Data'!AK4:AK53,'Raw Data'!AM4:AM53,'Raw Data'!AO4:AO53,'Raw Data'!AQ4:AQ53,'Raw Data'!AS4:AS53) | D8: =B8-C8 | E8: =MAX(0,MIN(100,100-D8*20)) | F8: =IF(D8<=1,"Healthy",IF(D8<=2,"Watch",IF(D8<=3,"Concern","High Risk"))) | G8: 0.15
A9: Innovation & Empowerment | B9: =AVERAGE('Raw Data'!AT4:AT53,'Raw Data'!AV4:AV53,'Raw Data'!AX4:AX53,'Raw Data'!AZ4:AZ53,'Raw Data'!BB4:BB53) | C9: =AVERAGE('Raw Data'!AU4:AU53,'Raw Data'!AW4:AW53,'Raw Data'!AY4:AY53,'Raw Data'!BA4:BA53,'Raw Data'!BC4:BC53) | D9: =B9-C9 | E9: =MAX(0,MIN(100,100-D9*20)) | F9: =IF(D9<=1,"Healthy",IF(D9<=2,"Watch",IF(D9<=3,"Concern","High Risk"))) | G9: 0.15
A10: Rewards & Growth | B10: =AVERAGE('Raw Data'!BD4:BD53,'Raw Data'!BF4:BF53,'Raw Data'!BH4:BH53,'Raw Data'!BJ4:BJ53,'Raw Data'!BL4:BL53) | C10: =AVERAGE('Raw Data'!BE4:BE53,'Raw Data'!BG4:BG53,'Raw Data'!BI4:BI53,'Raw Data'!BK4:BK53,'Raw Data'!BM4:BM53) | D10: =B10-C10 | E10: =MAX(0,MIN(100,100-D10*20)) | F10: =IF(D10<=1,"Healthy",IF(D10<=2,"Watch",IF(D10<=3,"Concern","High Risk"))) | G10: 0.15
A11: Overall Experience Index | B11: =SUMPRODUCT(E5:E10,G5:G10)/SUM(G5:G10)
A12: Retention Risk Score | B12: =ROUND(MIN(100,100*((MAX(0,D6)*0.25)+(MAX(0,D8)*0.20)+(MAX(0,D10)*0.20)+(MAX(0,D5)*0.15)+(MAX(0,D7)*0.10)+(MAX(0,D9)*0.10))/9),1)
A13: Retention Risk Classification | B13: =IF(B12<=20,"Very Low Risk",IF(B12<=40,"Low Risk",IF(B12<=60,"Moderate Risk",IF(B12<=80,"High Risk","Critical Risk"))))
A15: Per-Respondent Dimension Scores & Overall Index
A16: RespID | B16: Department | C16: Location | D16: Business Unit | E16: Manager | F16: JF_P_Avg | G16: JF_E_Avg | H16: JF_Gap | I16: ME_P_Avg | J16: ME_E_Avg | K16: ME_Gap | L16: TC_P_Avg | M16: TC_E_Avg | N16: TC_Gap | O16: WC_P_Avg | P16: WC_E_Avg | Q16: WC_Gap | R16: IE_P_Avg | S16: IE_E_Avg | T16: IE_Gap | U16: RG_P_Avg | V16: RG_E_Avg | W16: RG_Gap | X16: Overall_P | Y16: Overall_E | Z16: Overall_Gap | AA16: Retention_Risk | AB16: Turnover_Prob%
A17: =IF('Raw Data'!A4<>"",'Raw Data'!A4,"") | B17: =IF('Raw Data'!B4<>"",'Raw Data'!B4,"") | C17: =IF('Raw Data'!C4<>"",'Raw Data'!C4,"") | D17: =IF('Raw Data'!D4<>"",'Raw Data'!D4,"") | E17: =IF('Raw Data'!E4<>"",'Raw Data'!E4,"") | F17: =IF('Raw Data'!A4<>"",AVERAGE('Raw Data'!F4,'Raw Data'!H4,'Raw Data'!J4,'Raw Data'!L4,'Raw Data'!N4),"") | G17: =IF('Raw Data'!A4<>"",AVERAGE('Raw Data'!G4,'Raw Data'!I4,'Raw Data'!K4,'Raw Data'!M4,'Raw Data'!O4),"") | H17: =IF(F17<>"",F17-G17,"") | I17: =IF('Raw Data'!A4<>"",AVERAGE('Raw Data'!P4,'Raw Data'!R4,'Raw Data'!T4,'Raw Data'!V4,'Raw Data'!X4),"") | J17: =IF('Raw Data'!A4<>"",AVERAGE('Raw Data'!Q4,'Raw Data'!S4,'Raw Data'!U4,'Raw Data'!W4,'Raw Data'!Y4),"") | K17: =IF(I17<>"",I17-J17,"") | L17: =IF('Raw Data'!A4<>"",AVERAGE('Raw Data'!Z4,'Raw Data'!AB4,'Raw Data'!AD4,'Raw Data'!AF4,'Raw Data'!AH4),"") | M17: =IF('Raw Data'!A4<>"",AVERAGE('Raw Data'!AA4,'Raw Data'!AC4,'Raw Data'!AE4,'Raw Data'!AG4,'Raw Data'!AI4),"") | N17: =IF(L17<>"",L17-M17,"") | O17: =IF('Raw Data'!A4<>"",AVERAGE('Raw Data'!AJ4,'Raw Data'!AL4,'Raw Data'!AN4,'Raw Data'!AP4,'Raw Data'!AR4),"") | P17: =IF('Raw Data'!A4<>"",AVERAGE('Raw Data'!AK4,'Raw Data'!AM4,'Raw Data'!AO4,'Raw Data'!AQ4,'Raw Data'!AS4),"") | Q17: =IF(O17<>"",O17-P17,"") | R17: =IF('Raw Data'!A4<>"",AVERAGE('Raw Data'!AT4,'Raw Data'!AV4,'Raw Data'!AX4,'Raw Data'!AZ4,'Raw Data'!BB4),"") | S17: =IF('Raw Data'!A4<>"",AVERAGE('Raw Data'!AU4,'Raw Data'!AW4,'Raw Data'!AY4,'Raw Data'!BA4,'Raw Data'!BC4),"") | T17: =IF(R17<>"",R17-S17,"") | U17: =IF('Raw Data'!A4<>"",AVERAGE('Raw Data'!BD4,'Raw Data'!BF4,'Raw Data'!BH4,'Raw Data'!BJ4,'Raw Data'!BL4),"") | V17: =IF('Raw Data'!A4<>"",AVERAGE('Raw Data'!BE4,'Raw Data'!BG4,'Raw Data'!BI4,'Raw Data'!BK4,'Raw Data'!BM4),"") | W17: =IF(U17<>"",U17-V17,"") | X17: =IF(A17<>"",AVERAGE(F17,I17,L17,O17,R17,U17),"") | Y17: =IF(A17<>"",AVERAGE(G17,J17,M17,P17,S17,V17),"") | Z17: =IF(A17<>"",X17-Y17,"") | AA17: =IF(A17<>"",ROUND(MIN(100,100*((MAX(0,K17)*0.25)+(MAX(0,Q17)*0.20)+(MAX(0,W17)*0.20)+(MAX(0,H17)*0.15)+(MAX(0,N17)*0.10)+(MAX(0,T17)*0.10))/9),1),"") | AB17: =IF(A17<>"",MIN(1,(0.5*AA17/100)+(0.3*MAX(0,K17)/9)+(0.2*MAX(0,Q17)/9)),"")
A18: =IF('Raw Data'!A5<>"",'Raw Data'!A5,"") | B18: =IF('Raw Data'!B5<>"",'Raw Data'!B5,"") | C18: =IF('Raw Data'!C5<>"",'Raw Data'!C5,"") | D18: =IF('Raw Data'!D5<>"",'Raw Data'!D5,"") | E18: =IF('Raw Data'!E5<>"",'Raw Data'!E5,"") | F18: =IF('Raw Data'!A5<>"",AVERAGE('Raw Data'!F5,'Raw Data'!H5,'Raw Data'!J5,'Raw Data'!L5,'Raw Data'!N5),"") | G18: =IF('Raw Data'!A5<>"",AVERAGE('Raw Data'!G5,'Raw Data'!I5,'Raw Data'!K5,'Raw Data'!M5,'Raw Data'!O5),"") | H18: =IF(F18<>"",F18-G18,"") | I18: =IF('Raw Data'!A5<>"",AVERAGE('Raw Data'!P5,'Raw Data'!R5,'Raw Data'!T5,'Raw Data'!V5,'Raw Data'!X5),"") | J18: =IF('Raw Data'!A5<>"",AVERAGE('Raw Data'!Q5,'Raw Data'!S5,'Raw Data'!U5,'Raw Data'!W5,'Raw Data'!Y5),"") | K18: =IF(I18<>"",I18-J18,"") | L18: =IF('Raw Data'!A5<>"",AVERAGE('Raw Data'!Z5,'Raw Data'!AB5,'Raw Data'!AD5,'Raw Data'!AF5,'Raw Data'!AH5),"") | M18: =IF('Raw Data'!A5<>"",AVERAGE('Raw Data'!AA5,'Raw Data'!AC5,'Raw Data'!AE5,'Raw Data'!AG5,'Raw Data'!AI5),"") | N18: =IF(L18<>"",L18-M18,"") | O18: =IF('Raw Data'!A5<>"",AVERAGE('Raw Data'!AJ5,'Raw Data'!AL5,'Raw Data'!AN5,'Raw Data'!AP5,'Raw Data'!AR5),"") | P18: =IF('Raw Data'!A5<>"",AVERAGE('Raw Data'!AK5,'Raw Data'!AM5,'Raw Data'!AO5,'Raw Data'!AQ5,'Raw Data'!AS5),"") | Q18: =IF(O18<>"",O18-P18,"") | R18: =IF('Raw Data'!A5<>"",AVERAGE('Raw Data'!AT5,'Raw Data'!AV5,'Raw Data'!AX5,'Raw Data'!AZ5,'Raw Data'!BB5),"") | S18: =IF('Raw Data'!A5<>"",AVERAGE('Raw Data'!AU5,'Raw Data'!AW5,'Raw Data'!AY5,'Raw Data'!BA5,'Raw Data'!BC5),"") | T18: =IF(R18<>"",R18-S18,"") | U18: =IF('Raw Data'!A5<>"",AVERAGE('Raw Data'!BD5,'Raw Data'!BF5,'Raw Data'!BH5,'Raw Data'!BJ5,'Raw Data'!BL5),"") | V18: =IF('Raw Data'!A5<>"",AVERAGE('Raw Data'!BE5,'Raw Data'!BG5,'Raw Data'!BI5,'Raw Data'!BK5,'Raw Data'!BM5),"") | W18: =IF(U18<>"",U18-V18,"") | X18: =IF(A18<>"",AVERAGE(F18,I18,L18,O18,R18,U18),"") | Y18: =IF(A18<>"",AVERAGE(G18,J18,M18,P18,S18,V18),"") | Z18: =IF(A18<>"",X18-Y18,"") | AA18: =IF(A18<>"",ROUND(MIN(100,100*((MAX(0,K18)*0.25)+(MAX(0,Q18)*0.20)+(MAX(0,W18)*0.20)+(MAX(0,H18)*0.15)+(MAX(0,N18)*0.10)+(MAX(0,T18)*0.10))/9),1),"") | AB18: =IF(A18<>"",MIN(1,(0.5*AA18/100)+(0.3*MAX(0,K18)/9)+(0.2*MAX(0,Q18)/9)),"")
A19: =IF('Raw Data'!A6<>"",'Raw Data'!A6,"") | B19: =IF('Raw Data'!B6<>"",'Raw Data'!B6,"") | C19: =IF('Raw Data'!C6<>"",'Raw Data'!C6,"") | D19: =IF('Raw Data'!D6<>"",'Raw Data'!D6,"") | E19: =IF('Raw Data'!E6<>"",'Raw Data'!E6,"") | F19: =IF('Raw Data'!A6<>"",AVERAGE('Raw Data'!F6,'Raw Data'!H6,'Raw Data'!J6,'Raw Data'!L6,'Raw Data'!N6),"") | G19: =IF('Raw Data'!A6<>"",AVERAGE('Raw Data'!G6,'Raw Data'!I6,'Raw Data'!K6,'Raw Data'!M6,'Raw Data'!O6),"") | H19: =IF(F19<>"",F19-G19,"") | I19: =IF('Raw Data'!A6<>"",AVERAGE('Raw Data'!P6,'Raw Data'!R6,'Raw Data'!T6,'Raw Data'!V6,'Raw Data'!X6),"") | J19: =IF('Raw Data'!A6<>"",AVERAGE('Raw Data'!Q6,'Raw Data'!S6,'Raw Data'!U6,'Raw Data'!W6,'Raw Data'!Y6),"") | K19: =IF(I19<>"",I19-J19,"") | L19: =IF('Raw Data'!A6<>"",AVERAGE('Raw Data'!Z6,'Raw Data'!AB6,'Raw Data'!AD6,'Raw Data'!AF6,'Raw Data'!AH6),"") | M19: =IF('Raw Data'!A6<>"",AVERAGE('Raw Data'!AA6,'Raw Data'!AC6,'Raw Data'!AE6,'Raw Data'!AG6,'Raw Data'!AI6),"") | N19: =IF(L19<>"",L19-M19,"") | O19: =IF('Raw Data'!A6<>"",AVERAGE('Raw Data'!AJ6,'Raw Data'!AL6,'Raw Data'!AN6,'Raw Data'!AP6,'Raw Data'!AR6),"") | P19: =IF('Raw Data'!A6<>"",AVERAGE('Raw Data'!AK6,'Raw Data'!AM6,'Raw Data'!AO6,'Raw Data'!AQ6,'Raw Data'!AS6),"") | Q19: =IF(O19<>"",O19-P19,"") | R19: =IF('Raw Data'!A6<>"",AVERAGE('Raw Data'!AT6,'Raw Data'!AV6,'Raw Data'!AX6,'Raw Data'!AZ6,'Raw Data'!BB6),"") | S19: =IF('Raw Data'!A6<>"",AVERAGE('Raw Data'!AU6,'Raw Data'!AW6,'Raw Data'!AY6,'Raw Data'!BA6,'Raw Data'!BC6),"") | T19: =IF(R19<>"",R19-S19,"") | U19: =IF('Raw Data'!A6<>"",AVERAGE('Raw Data'!BD6,'Raw Data'!BF6,'Raw Data'!BH6,'Raw Data'!BJ6,'Raw Data'!BL6),"") | V19: =IF('Raw Data'!A6<>"",AVERAGE('Raw Data'!BE6,'Raw Data'!BG6,'Raw Data'!BI6,'Raw Data'!BK6,'Raw Data'!BM6),"") | W19: =IF(U19<>"",U19-V19,"") | X19: =IF(A19<>"",AVERAGE(F19,I19,L19,O19,R19,U19),"") | Y19: =IF(A19<>"",AVERAGE(G19,J19,M19,P19,S19,V19),"") | Z19: =IF(A19<>"",X19-Y19,"") | AA19: =IF(A19<>"",ROUND(MIN(100,100*((MAX(0,K19)*0.25)+(MAX(0,Q19)*0.20)+(MAX(0,W19)*0.20)+(MAX(0,H19)*0.15)+(MAX(0,N19)*0.10)+(MAX(0,T19)*0.10))/9),1),"") | AB19: =IF(A19<>"",MIN(1,(0.5*AA19/100)+(0.3*MAX(0,K19)/9)+(0.2*MAX(0,Q19)/9)),"")
A20: =IF('Raw Data'!A7<>"",'Raw Data'!A7,"") | B20: =IF('Raw Data'!B7<>"",'Raw Data'!B7,"") | C20: =IF('Raw Data'!C7<>"",'Raw Data'!C7,"") | D20: =IF('Raw Data'!D7<>"",'Raw Data'!D7,"") | E20: =IF('Raw Data'!E7<>"",'Raw Data'!E7,"") | F20: =IF('Raw Data'!A7<>"",AVERAGE('Raw Data'!F7,'Raw Data'!H7,'Raw Data'!J7,'Raw Data'!L7,'Raw Data'!N7),"") | G20: =IF('Raw Data'!A7<>"",AVERAGE('Raw Data'!G7,'Raw Data'!I7,'Raw Data'!K7,'Raw Data'!M7,'Raw Data'!O7),"") | H20: =IF(F20<>"",F20-G20,"") | I20: =IF('Raw Data'!A7<>"",AVERAGE('Raw Data'!P7,'Raw Data'!R7,'Raw Data'!T7,'Raw Data'!V7,'Raw Data'!X7),"") | J20: =IF('Raw Data'!A7<>"",AVERAGE('Raw Data'!Q7,'Raw Data'!S7,'Raw Data'!U7,'Raw Data'!W7,'Raw Data'!Y7),"") | K20: =IF(I20<>"",I20-J20,"") | L20: =IF('Raw Data'!A7<>"",AVERAGE('Raw Data'!Z7,'Raw Data'!AB7,'Raw Data'!AD7,'Raw Data'!AF7,'Raw Data'!AH7),"") | M20: =IF('Raw Data'!A7<>"",AVERAGE('Raw Data'!AA7,'Raw Data'!AC7,'Raw Data'!AE7,'Raw Data'!AG7,'Raw Data'!AI7),"") | N20: =IF(L20<>"",L20-M20,"") | O20: =IF('Raw Data'!A7<>"",AVERAGE('Raw Data'!AJ7,'Raw Data'!AL7,'Raw Data'!AN7,'Raw Data'!AP7,'Raw Data'!AR7),"") | P20: =IF('Raw Data'!A7<>"",AVERAGE('Raw Data'!AK7,'Raw Data'!AM7,'Raw Data'!AO7,'Raw Data'!AQ7,'Raw Data'!AS7),"") | Q20: =IF(O20<>"",O20-P20,"") | R20: =IF('Raw Data'!A7<>"",AVERAGE('Raw Data'!AT7,'Raw Data'!AV7,'Raw Data'!AX7,'Raw Data'!AZ7,'Raw Data'!BB7),"") | S20: =IF('Raw Data'!A7<>"",AVERAGE('Raw Data'!AU7,'Raw Data'!AW7,'Raw Data'!AY7,'Raw Data'!BA7,'Raw Data'!BC7),"") | T20: =IF(R20<>"",R20-S20,"") | U20: =IF('Raw Data'!A7<>"",AVERAGE('Raw Data'!BD7,'Raw Data'!BF7,'Raw Data'!BH7,'Raw Data'!BJ7,'Raw Data'!BL7),"") | V20: =IF('Raw Data'!A7<>"",AVERAGE('Raw Data'!BE7,'Raw Data'!BG7,'Raw Data'!BI7,'Raw Data'!BK7,'Raw Data'!BM7),"") | W20: =IF(U20<>"",U20-V20,"") | X20: =IF(A20<>"",AVERAGE(F20,I20,L20,O20,R20,U20),"") | Y20: =IF(A20<>"",AVERAGE(G20,J20,M20,P20,S20,V20),"") | Z20: =IF(A20<>"",X20-Y20,"") | AA20: =IF(A20<>"",ROUND(MIN(100,100*((MAX(0,K20)*0.25)+(MAX(0,Q20)*0.20)+(MAX(0,W20)*0.20)+(MAX(0,H20)*0.15)+(MAX(0,N20)*0.10)+(MAX(0,T20)*0.10))/9),1),"") | AB20: =IF(A20<>"",MIN(1,(0.5*AA20/100)+(0.3*MAX(0,K20)/9)+(0.2*MAX(0,Q20)/9)),"")
A21: =IF('Raw Data'!A8<>"",'Raw Data'!A8,"") | B21: =IF('Raw Data'!B8<>"",'Raw Data'!B8,"") | C21: =IF('Raw Data'!C8<>"",'Raw Data'!C8,"") | D21: =IF('Raw Data'!D8<>"",'Raw Data'!D8,"") | E21: =IF('Raw Data'!E8<>"",'Raw Data'!E8,"") | F21: =IF('Raw Data'!A8<>"",AVERAGE('Raw Data'!F8,'Raw Data'!H8,'Raw Data'!J8,'Raw Data'!L8,'Raw Data'!N8),"") | G21: =IF('Raw Data'!A8<>"",AVERAGE('Raw Data'!G8,'Raw Data'!I8,'Raw Data'!K8,'Raw Data'!M8,'Raw Data'!O8),"") | H21: =IF(F21<>"",F21-G21,"") | I21: =IF('Raw Data'!A8<>"",AVERAGE('Raw Data'!P8,'Raw Data'!R8,'Raw Data'!T8,'Raw Data'!V8,'Raw Data'!X8),"") | J21: =IF('Raw Data'!A8<>"",AVERAGE('Raw Data'!Q8,'Raw Data'!S8,'Raw Data'!U8,'Raw Data'!W8,'Raw Data'!Y8),"") | K21: =IF(I21<>"",I21-J21,"") | L21: =IF('Raw Data'!A8<>"",AVERAGE('Raw Data'!Z8,'Raw Data'!AB8,'Raw Data'!AD8,'Raw Data'!AF8,'Raw Data'!AH8),"") | M21: =IF('Raw Data'!A8<>"",AVERAGE('Raw Data'!AA8,'Raw Data'!AC8,'Raw Data'!AE8,'Raw Data'!AG8,'Raw Data'!AI8),"") | N21: =IF(L21<>"",L21-M21,"") | O21: =IF('Raw Data'!A8<>"",AVERAGE('Raw Data'!AJ8,'Raw Data'!AL8,'Raw Data'!AN8,'Raw Data'!AP8,'Raw Data'!AR8),"") | P21: =IF('Raw Data'!A8<>"",AVERAGE('Raw Data'!AK8,'Raw Data'!AM8,'Raw Data'!AO8,'Raw Data'!AQ8,'Raw Data'!AS8),"") | Q21: =IF(O21<>"",O21-P21,"") | R21: =IF('Raw Data'!A8<>"",AVERAGE('Raw Data'!AT8,'Raw Data'!AV8,'Raw Data'!AX8,'Raw Data'!AZ8,'Raw Data'!BB8),"") | S21: =IF('Raw Data'!A8<>"",AVERAGE('Raw Data'!AU8,'Raw Data'!AW8,'Raw Data'!AY8,'Raw Data'!BA8,'Raw Data'!BC8),"") | T21: =IF(R21<>"",R21-S21,"") | U21: =IF('Raw Data'!A8<>"",AVERAGE('Raw Data'!BD8,'Raw Data'!BF8,'Raw Data'!BH8,'Raw Data'!BJ8,'Raw Data'!BL8),"") | V21: =IF('Raw Data'!A8<>"",AVERAGE('Raw Data'!BE8,'Raw Data'!BG8,'Raw Data'!BI8,'Raw Data'!BK8,'Raw Data'!BM8),"") | W21: =IF(U21<>"",U21-V21,"") | X21: =IF(A21<>"",AVERAGE(F21,I21,L21,O21,R21,U21),"") | Y21: =IF(A21<>"",AVERAGE(G21,J21,M21,P21,S21,V21),"") | Z21: =IF(A21<>"",X21-Y21,"") | AA21: =IF(A21<>"",ROUND(MIN(100,100*((MAX(0,K21)*0.25)+(MAX(0,Q21)*0.20)+(MAX(0,W21)*0.20)+(MAX(0,H21)*0.15)+(MAX(0,N21)*0.10)+(MAX(0,T21)*0.10))/9),1),"") | AB21: =IF(A21<>"",MIN(1,(0.5*AA21/100)+(0.3*MAX(0,K21)/9)+(0.2*MAX(0,Q21)/9)),"")
A22: =IF('Raw Data'!A9<>"",'Raw Data'!A9,"") | B22: =IF('Raw Data'!B9<>"",'Raw Data'!B9,"") | C22: =IF('Raw Data'!C9<>"",'Raw Data'!C9,"") | D22: =IF('Raw Data'!D9<>"",'Raw Data'!D9,"") | E22: =IF('Raw Data'!E9<>"",'Raw Data'!E9,"") | F22: =IF('Raw Data'!A9<>"",AVERAGE('Raw Data'!F9,'Raw Data'!H9,'Raw Data'!J9,'Raw Data'!L9,'Raw Data'!N9),"") | G22: =IF('Raw Data'!A9<>"",AVERAGE('Raw Data'!G9,'Raw Data'!I9,'Raw Data'!K9,'Raw Data'!M9,'Raw Data'!O9),"") | H22: =IF(F22<>"",F22-G22,"") | I22: =IF('Raw Data'!A9<>"",AVERAGE('Raw Data'!P9,'Raw Data'!R9,'Raw Data'!T9,'Raw Data'!V9,'Raw Data'!X9),"") | J22: =IF('Raw Data'!A9<>"",AVERAGE('Raw Data'!Q9,'Raw Data'!S9,'Raw Data'!U9,'Raw Data'!W9,'Raw Data'!Y9),"") | K22: =IF(I22<>"",I22-J22,"") | L22: =IF('Raw Data'!A9<>"",AVERAGE('Raw Data'!Z9,'Raw Data'!AB9,'Raw Data'!AD9,'Raw Data'!AF9,'Raw Data'!AH9),"") | M22: =IF('Raw Data'!A9<>"",AVERAGE('Raw Data'!AA9,'Raw Data'!AC9,'Raw Data'!AE9,'Raw Data'!AG9,'Raw Data'!AI9),"") | N22: =IF(L22<>"",L22-M22,"") | O22: =IF('Raw Data'!A9<>"",AVERAGE('Raw Data'!AJ9,'Raw Data'!AL9,'Raw Data'!AN9,'Raw Data'!AP9,'Raw Data'!AR9),"") | P22: =IF('Raw Data'!A9<>"",AVERAGE('Raw Data'!AK9,'Raw Data'!AM9,'Raw Data'!AO9,'Raw Data'!AQ9,'Raw Data'!AS9),"") | Q22: =IF(O22<>"",O22-P22,"") | R22: =IF('Raw Data'!A9<>"",AVERAGE('Raw Data'!AT9,'Raw Data'!AV9,'Raw Data'!AX9,'Raw Data'!AZ9,'Raw Data'!BB9),"") | S22: =IF('Raw Data'!A9<>"",AVERAGE('Raw Data'!AU9,'Raw Data'!AW9,'Raw Data'!AY9,'Raw Data'!BA9,'Raw Data'!BC9),"") | T22: =IF(R22<>"",R22-S22,"") | U22: =IF('Raw Data'!A9<>"",AVERAGE('Raw Data'!BD9,'Raw Data'!BF9,'Raw Data'!BH9,'Raw Data'!BJ9,'Raw Data'!BL9),"") | V22: =IF('Raw Data'!A9<>"",AVERAGE('Raw Data'!BE9,'Raw Data'!BG9,'Raw Data'!BI9,'Raw Data'!BK9,'Raw Data'!BM9),"") | W22: =IF(U22<>"",U22-V22,"") | X22: =IF(A22<>"",AVERAGE(F22,I22,L22,O22,R22,U22),"") | Y22: =IF(A22<>"",AVERAGE(G22,J22,M22,P22,S22,V22),"") | Z22: =IF(A22<>"",X22-Y22,"") | AA22: =IF(A22<>"",ROUND(MIN(100,100*((MAX(0,K22)*0.25)+(MAX(0,Q22)*0.20)+(MAX(0,W22)*0.20)+(MAX(0,H22)*0.15)+(MAX(0,N22)*0.10)+(MAX(0,T22)*0.10))/9),1),"") | AB22: =IF(A22<>"",MIN(1,(0.5*AA22/100)+(0.3*MAX(0,K22)/9)+(0.2*MAX(0,Q22)/9)),"")
A23: =IF('Raw Data'!A10<>"",'Raw Data'!A10,"") | B23: =IF('Raw Data'!B10<>"",'Raw Data'!B10,"") | C23: =IF('Raw Data'!C10<>"",'Raw Data'!C10,"") | D23: =IF('Raw Data'!D10<>"",'Raw Data'!D10,"") | E23: =IF('Raw Data'!E10<>"",'Raw Data'!E10,"") | F23: =IF('Raw Data'!A10<>"",AVERAGE('Raw Data'!F10,'Raw Data'!H10,'Raw Data'!J10,'Raw Data'!L10,'Raw Data'!N10),"") | G23: =IF('Raw Data'!A10<>"",AVERAGE('Raw Data'!G10,'Raw Data'!I10,'Raw Data'!K10,'Raw Data'!M10,'Raw Data'!O10),"") | H23: =IF(F23<>"",F23-G23,"") | I23: =IF('Raw Data'!A10<>"",AVERAGE('Raw Data'!P10,'Raw Data'!R10,'Raw Data'!T10,'Raw Data'!V10,'Raw Data'!X10),"") | J23: =IF('Raw Data'!A10<>"",AVERAGE('Raw Data'!Q10,'Raw Data'!S10,'Raw Data'!U10,'Raw Data'!W10,'Raw Data'!Y10),"") | K23: =IF(I23<>"",I23-J23,"") | L23: =IF('Raw Data'!A10<>"",AVERAGE('Raw Data'!Z10,'Raw Data'!AB10,'Raw Data'!AD10,'Raw Data'!AF10,'Raw Data'!AH10),"") | M23: =IF('Raw Data'!A10<>"",AVERAGE('Raw Data'!AA10,'Raw Data'!AC10,'Raw Data'!AE10,'Raw Data'!AG10,'Raw Data'!AI10),"") | N23: =IF(L23<>"",L23-M23,"") | O23: =IF('Raw Data'!A10<>"",AVERAGE('Raw Data'!AJ10,'Raw Data'!AL10,'Raw Data'!AN10,'Raw Data'!AP10,'Raw Data'!AR10),"") | P23: =IF('Raw Data'!A10<>"",AVERAGE('Raw Data'!AK10,'Raw Data'!AM10,'Raw Data'!AO10,'Raw Data'!AQ10,'Raw Data'!AS10),"") | Q23: =IF(O23<>"",O23-P23,"") | R23: =IF('Raw Data'!A10<>"",AVERAGE('Raw Data'!AT10,'Raw Data'!AV10,'Raw Data'!AX10,'Raw Data'!AZ10,'Raw Data'!BB10),"") | S23: =IF('Raw Data'!A10<>"",AVERAGE('Raw Data'!AU10,'Raw Data'!AW10,'Raw Data'!AY10,'Raw Data'!BA10,'Raw Data'!BC10),"") | T23: =IF(R23<>"",R23-S23,"") | U23: =IF('Raw Data'!A10<>"",AVERAGE('Raw Data'!BD10,'Raw Data'!BF10,'Raw Data'!BH10,'Raw Data'!BJ10,'Raw Data'!BL10),"") | V23: =IF('Raw Data'!A10<>"",AVERAGE('Raw Data'!BE10,'Raw Data'!BG10,'Raw Data'!BI10,'Raw Data'!BK10,'Raw Data'!BM10),"") | W23: =IF(U23<>"",U23-V23,"") | X23: =IF(A23<>"",AVERAGE(F23,I23,L23,O23,R23,U23),"") | Y23: =IF(A23<>"",AVERAGE(G23,J23,M23,P23,S23,V23),"") | Z23: =IF(A23<>"",X23-Y23,"") | AA23: =IF(A23<>"",ROUND(MIN(100,100*((MAX(0,K23)*0.25)+(MAX(0,Q23)*0.20)+(MAX(0,W23)*0.20)+(MAX(0,H23)*0.15)+(MAX(0,N23)*0.10)+(MAX(0,T23)*0.10))/9),1),"") | AB23: =IF(A23<>"",MIN(1,(0.5*AA23/100)+(0.3*MAX(0,K23)/9)+(0.2*MAX(0,Q23)/9)),"")
A24: =IF('Raw Data'!A11<>"",'Raw Data'!A11,"") | B24: =IF('Raw Data'!B11<>"",'Raw Data'!B11,"") | C24: =IF('Raw Data'!C11<>"",'Raw Data'!C11,"") | D24: =IF('Raw Data'!D11<>"",'Raw Data'!D11,"") | E24: =IF('Raw Data'!E11<>"",'Raw Data'!E11,"") | F24: =IF('Raw Data'!A11<>"",AVERAGE('Raw Data'!F11,'Raw Data'!H11,'Raw Data'!J11,'Raw Data'!L11,'Raw Data'!N11),"") | G24: =IF('Raw Data'!A11<>"",AVERAGE('Raw Data'!G11,'Raw Data'!I11,'Raw Data'!K11,'Raw Data'!M11,'Raw Data'!O11),"") | H24: =IF(F24<>"",F24-G24,"") | I24: =IF('Raw Data'!A11<>"",AVERAGE('Raw Data'!P11,'Raw Data'!R11,'Raw Data'!T11,'Raw Data'!V11,'Raw Data'!X11),"") | J24: =IF('Raw Data'!A11<>"",AVERAGE('Raw Data'!Q11,'Raw Data'!S11,'Raw Data'!U11,'Raw Data'!W11,'Raw Data'!Y11),"") | K24: =IF(I24<>"",I24-J24,"") | L24: =IF('Raw Data'!A11<>"",AVERAGE('Raw Data'!Z11,'Raw Data'!AB11,'Raw Data'!AD11,'Raw Data'!AF11,'Raw Data'!AH11),"") | M24: =IF('Raw Data'!A11<>"",AVERAGE('Raw Data'!AA11,'Raw Data'!AC11,'Raw Data'!AE11,'Raw Data'!AG11,'Raw Data'!AI11),"") | N24: =IF(L24<>"",L24-M24,"") | O24: =IF('Raw Data'!A11<>"",AVERAGE('Raw Data'!AJ11,'Raw Data'!AL11,'Raw Data'!AN11,'Raw Data'!AP11,'Raw Data'!AR11),"") | P24: =IF('Raw Data'!A11<>"",AVERAGE('Raw Data'!AK11,'Raw Data'!AM11,'Raw Data'!AO11,'Raw Data'!AQ11,'Raw Data'!AS11),"") | Q24: =IF(O24<>"",O24-P24,"") | R24: =IF('Raw Data'!A11<>"",AVERAGE('Raw Data'!AT11,'Raw Data'!AV11,'Raw Data'!AX11,'Raw Data'!AZ11,'Raw Data'!BB11),"") | S24: =IF('Raw Data'!A11<>"",AVERAGE('Raw Data'!AU11,'Raw Data'!AW11,'Raw Data'!AY11,'Raw Data'!BA11,'Raw Data'!BC11),"") | T24: =IF(R24<>"",R24-S24,"") | U24: =IF('Raw Data'!A11<>"",AVERAGE('Raw Data'!BD11,'Raw Data'!BF11,'Raw Data'!BH11,'Raw Data'!BJ11,'Raw Data'!BL11),"") | V24: =IF('Raw Data'!A11<>"",AVERAGE('Raw Data'!BE11,'Raw Data'!BG11,'Raw Data'!BI11,'Raw Data'!BK11,'Raw Data'!BM11),"") | W24: =IF(U24<>"",U24-V24,"") | X24: =IF(A24<>"",AVERAGE(F24,I24,L24,O24,R24,U24),"") | Y24: =IF(A24<>"",AVERAGE(G24,J24,M24,P24,S24,V24),"") | Z24: =IF(A24<>"",X24-Y24,"") | AA24: =IF(A24<>"",ROUND(MIN(100,100*((MAX(0,K24)*0.25)+(MAX(0,Q24)*0.20)+(MAX(0,W24)*0.20)+(MAX(0,H24)*0.15)+(MAX(0,N24)*0.10)+(MAX(0,T24)*0.10))/9),1),"") | AB24: =IF(A24<>"",MIN(1,(0.5*AA24/100)+(0.3*MAX(0,K24)/9)+(0.2*MAX(0,Q24)/9)),"")
A25: =IF('Raw Data'!A12<>"",'Raw Data'!A12,"") | B25: =IF('Raw Data'!B12<>"",'Raw Data'!B12,"") | C25: =IF('Raw Data'!C12<>"",'Raw Data'!C12,"") | D25: =IF('Raw Data'!D12<>"",'Raw Data'!D12,"") | E25: =IF('Raw Data'!E12<>"",'Raw Data'!E12,"") | F25: =IF('Raw Data'!A12<>"",AVERAGE('Raw Data'!F12,'Raw Data'!H12,'Raw Data'!J12,'Raw Data'!L12,'Raw Data'!N12),"") | G25: =IF('Raw Data'!A12<>"",AVERAGE('Raw Data'!G12,'Raw Data'!I12,'Raw Data'!K12,'Raw Data'!M12,'Raw Data'!O12),"") | H25: =IF(F25<>"",F25-G25,"") | I25: =IF('Raw Data'!A12<>"",AVERAGE('Raw Data'!P12,'Raw Data'!R12,'Raw Data'!T12,'Raw Data'!V12,'Raw Data'!X12),"") | J25: =IF('Raw Data'!A12<>"",AVERAGE('Raw Data'!Q12,'Raw Data'!S12,'Raw Data'!U12,'Raw Data'!W12,'Raw Data'!Y12),"") | K25: =IF(I25<>"",I25-J25,"") | L25: =IF('Raw Data'!A12<>"",AVERAGE('Raw Data'!Z12,'Raw Data'!AB12,'Raw Data'!AD12,'Raw Data'!AF12,'Raw Data'!AH12),"") | M25: =IF('Raw Data'!A12<>"",AVERAGE('Raw Data'!AA12,'Raw Data'!AC12,'Raw Data'!AE12,'Raw Data'!AG12,'Raw Data'!AI12),"") | N25: =IF(L25<>"",L25-M25,"") | O25: =IF('Raw Data'!A12<>"",AVERAGE('Raw Data'!AJ12,'Raw Data'!AL12,'Raw Data'!AN12,'Raw Data'!AP12,'Raw Data'!AR12),"") | P25: =IF('Raw Data'!A12<>"",AVERAGE('Raw Data'!AK12,'Raw Data'!AM12,'Raw Data'!AO12,'Raw Data'!AQ12,'Raw Data'!AS12),"") | Q25: =IF(O25<>"",O25-P25,"") | R25: =IF('Raw Data'!A12<>"",AVERAGE('Raw Data'!AT12,'Raw Data'!AV12,'Raw Data'!AX12,'Raw Data'!AZ12,'Raw Data'!BB12),"") | S25: =IF('Raw Data'!A12<>"",AVERAGE('Raw Data'!AU12,'Raw Data'!AW12,'Raw Data'!AY12,'Raw Data'!BA12,'Raw Data'!BC12),"") | T25: =IF(R25<>"",R25-S25,"") | U25: =IF('Raw Data'!A12<>"",AVERAGE('Raw Data'!BD12,'Raw Data'!BF12,'Raw Data'!BH12,'Raw Data'!BJ12,'Raw Data'!BL12),"") | V25: =IF('Raw Data'!A12<>"",AVERAGE('Raw Data'!BE12,'Raw Data'!BG12,'Raw Data'!BI12,'Raw Data'!BK12,'Raw Data'!BM12),"") | W25: =IF(U25<>"",U25-V25,"") | X25: =IF(A25<>"",AVERAGE(F25,I25,L25,O25,R25,U25),"") | Y25: =IF(A25<>"",AVERAGE(G25,J25,M25,P25,S25,V25),"") | Z25: =IF(A25<>"",X25-Y25,"") | AA25: =IF(A25<>"",ROUND(MIN(100,100*((MAX(0,K25)*0.25)+(MAX(0,Q25)*0.20)+(MAX(0,W25)*0.20)+(MAX(0,H25)*0.15)+(MAX(0,N25)*0.10)+(MAX(0,T25)*0.10))/9),1),"") | AB25: =IF(A25<>"",MIN(1,(0.5*AA25/100)+(0.3*MAX(0,K25)/9)+(0.2*MAX(0,Q25)/9)),"")
A26: =IF('Raw Data'!A13<>"",'Raw Data'!A13,"") | B26: =IF('Raw Data'!B13<>"",'Raw Data'!B13,"") | C26: =IF('Raw Data'!C13<>"",'Raw Data'!C13,"") | D26: =IF('Raw Data'!D13<>"",'Raw Data'!D13,"") | E26: =IF('Raw Data'!E13<>"",'Raw Data'!E13,"") | F26: =IF('Raw Data'!A13<>"",AVERAGE('Raw Data'!F13,'Raw Data'!H13,'Raw Data'!J13,'Raw Data'!L13,'Raw Data'!N13),"") | G26: =IF('Raw Data'!A13<>"",AVERAGE('Raw Data'!G13,'Raw Data'!I13,'Raw Data'!K13,'Raw Data'!M13,'Raw Data'!O13),"") | H26: =IF(F26<>"",F26-G26,"") | I26: =IF('Raw Data'!A13<>"",AVERAGE('Raw Data'!P13,'Raw Data'!R13,'Raw Data'!T13,'Raw Data'!V13,'Raw Data'!X13),"") | J26: =IF('Raw Data'!A13<>"",AVERAGE('Raw Data'!Q13,'Raw Data'!S13,'Raw Data'!U13,'Raw Data'!W13,'Raw Data'!Y13),"") | K26: =IF(I26<>"",I26-J26,"") | L26: =IF('Raw Data'!A13<>"",AVERAGE('Raw Data'!Z13,'Raw Data'!AB13,'Raw Data'!AD13,'Raw Data'!AF13,'Raw Data'!AH13),"") | M26: =IF('Raw Data'!A13<>"",AVERAGE('Raw Data'!AA13,'Raw Data'!AC13,'Raw Data'!AE13,'Raw Data'!AG13,'Raw Data'!AI13),"") | N26: =IF(L26<>"",L26-M26,"") | O26: =IF('Raw Data'!A13<>"",AVERAGE('Raw Data'!AJ13,'Raw Data'!AL13,'Raw Data'!AN13,'Raw Data'!AP13,'Raw Data'!AR13),"") | P26: =IF('Raw Data'!A13<>"",AVERAGE('Raw Data'!AK13,'Raw Data'!AM13,'Raw Data'!AO13,'Raw Data'!AQ13,'Raw Data'!AS13),"") | Q26: =IF(O26<>"",O26-P26,"") | R26: =IF('Raw Data'!A13<>"",AVERAGE('Raw Data'!AT13,'Raw Data'!AV13,'Raw Data'!AX13,'Raw Data'!AZ13,'Raw Data'!BB13),"") | S26: =IF('Raw Data'!A13<>"",AVERAGE('Raw Data'!AU13,'Raw Data'!AW13,'Raw Data'!AY13,'Raw Data'!BA13,'Raw Data'!BC13),"") | T26: =IF(R26<>"",R26-S26,"") | U26: =IF('Raw Data'!A13<>"",AVERAGE('Raw Data'!BD13,'Raw Data'!BF13,'Raw Data'!BH13,'Raw Data'!BJ13,'Raw Data'!BL13),"") | V26: =IF('Raw Data'!A13<>"",AVERAGE('Raw Data'!BE13,'Raw Data'!BG13,'Raw Data'!BI13,'Raw Data'!BK13,'Raw Data'!BM13),"") | W26: =IF(U26<>"",U26-V26,"") | X26: =IF(A26<>"",AVERAGE(F26,I26,L26,O26,R26,U26),"") | Y26: =IF(A26<>"",AVERAGE(G26,J26,M26,P26,S26,V26),"") | Z26: =IF(A26<>"",X26-Y26,"") | AA26: =IF(A26<>"",ROUND(MIN(100,100*((MAX(0,K26)*0.25)+(MAX(0,Q26)*0.20)+(MAX(0,W26)*0.20)+(MAX(0,H26)*0.15)+(MAX(0,N26)*0.10)+(MAX(0,T26)*0.10))/9),1),"") | AB26: =IF(A26<>"",MIN(1,(0.5*AA26/100)+(0.3*MAX(0,K26)/9)+(0.2*MAX(0,Q26)/9)),"")
A27: =IF('Raw Data'!A14<>"",'Raw Data'!A14,"") | B27: =IF('Raw Data'!B14<>"",'Raw Data'!B14,"") | C27: =IF('Raw Data'!C14<>"",'Raw Data'!C14,"") | D27: =IF('Raw Data'!D14<>"",'Raw Data'!D14,"") | E27: =IF('Raw Data'!E14<>"",'Raw Data'!E14,"") | F27: =IF('Raw Data'!A14<>"",AVERAGE('Raw Data'!F14,'Raw Data'!H14,'Raw Data'!J14,'Raw Data'!L14,'Raw Data'!N14),"") | G27: =IF('Raw Data'!A14<>"",AVERAGE('Raw Data'!G14,'Raw Data'!I14,'Raw Data'!K14,'Raw Data'!M14,'Raw Data'!O14),"") | H27: =IF(F27<>"",F27-G27,"") | I27: =IF('Raw Data'!A14<>"",AVERAGE('Raw Data'!P14,'Raw Data'!R14,'Raw Data'!T14,'Raw Data'!V14,'Raw Data'!X14),"") | J27: =IF('Raw Data'!A14<>"",AVERAGE('Raw Data'!Q14,'Raw Data'!S14,'Raw Data'!U14,'Raw Data'!W14,'Raw Data'!Y14),"") | K27: =IF(I27<>"",I27-J27,"") | L27: =IF('Raw Data'!A14<>"",AVERAGE('Raw Data'!Z14,'Raw Data'!AB14,'Raw Data'!AD14,'Raw Data'!AF14,'Raw Data'!AH14),"") | M27: =IF('Raw Data'!A14<>"",AVERAGE('Raw Data'!AA14,'Raw Data'!AC14,'Raw Data'!AE14,'Raw Data'!AG14,'Raw Data'!AI14),"") | N27: =IF(L27<>"",L27-M27,"") | O27: =IF('Raw Data'!A14<>"",AVERAGE('Raw Data'!AJ14,'Raw Data'!AL14,'Raw Data'!AN14,'Raw Data'!AP14,'Raw Data'!AR14),"") | P27: =IF('Raw Data'!A14<>"",AVERAGE('Raw Data'!AK14,'Raw Data'!AM14,'Raw Data'!AO14,'Raw Data'!AQ14,'Raw Data'!AS14),"") | Q27: =IF(O27<>"",O27-P27,"") | R27: =IF('Raw Data'!A14<>"",AVERAGE('Raw Data'!AT14,'Raw Data'!AV14,'Raw Data'!AX14,'Raw Data'!AZ14,'Raw Data'!BB14),"") | S27: =IF('Raw Data'!A14<>"",AVERAGE('Raw Data'!AU14,'Raw Data'!AW14,'Raw Data'!AY14,'Raw Data'!BA14,'Raw Data'!BC14),"") | T27: =IF(R27<>"",R27-S27,"") | U27: =IF('Raw Data'!A14<>"",AVERAGE('Raw Data'!BD14,'Raw Data'!BF14,'Raw Data'!BH14,'Raw Data'!BJ14,'Raw Data'!BL14),"") | V27: =IF('Raw Data'!A14<>"",AVERAGE('Raw Data'!BE14,'Raw Data'!BG14,'Raw Data'!BI14,'Raw Data'!BK14,'Raw Data'!BM14),"") | W27: =IF(U27<>"",U27-V27,"") | X27: =IF(A27<>"",AVERAGE(F27,I27,L27,O27,R27,U27),"") | Y27: =IF(A27<>"",AVERAGE(G27,J27,M27,P27,S27,V27),"") | Z27: =IF(A27<>"",X27-Y27,"") | AA27: =IF(A27<>"",ROUND(MIN(100,100*((MAX(0,K27)*0.25)+(MAX(0,Q27)*0.20)+(MAX(0,W27)*0.20)+(MAX(0,H27)*0.15)+(MAX(0,N27)*0.10)+(MAX(0,T27)*0.10))/9),1),"") | AB27: =IF(A27<>"",MIN(1,(0.5*AA27/100)+(0.3*MAX(0,K27)/9)+(0.2*MAX(0,Q27)/9)),"")
A28: =IF('Raw Data'!A15<>"",'Raw Data'!A15,"") | B28: =IF('Raw Data'!B15<>"",'Raw Data'!B15,"") | C28: =IF('Raw Data'!C15<>"",'Raw Data'!C15,"") | D28: =IF('Raw Data'!D15<>"",'Raw Data'!D15,"") | E28: =IF('Raw Data'!E15<>"",'Raw Data'!E15,"") | F28: =IF('Raw Data'!A15<>"",AVERAGE('Raw Data'!F15,'Raw Data'!H15,'Raw Data'!J15,'Raw Data'!L15,'Raw Data'!N15),"") | G28: =IF('Raw Data'!A15<>"",AVERAGE('Raw Data'!G15,'Raw Data'!I15,'Raw Data'!K15,'Raw Data'!M15,'Raw Data'!O15),"") | H28: =IF(F28<>"",F28-G28,"") | I28: =IF('Raw Data'!A15<>"",AVERAGE('Raw Data'!P15,'Raw Data'!R15,'Raw Data'!T15,'Raw Data'!V15,'Raw Data'!X15),"") | J28: =IF('Raw Data'!A15<>"",AVERAGE('Raw Data'!Q15,'Raw Data'!S15,'Raw Data'!U15,'Raw Data'!W15,'Raw Data'!Y15),"") | K28: =IF(I28<>"",I28-J28,"") | L28: =IF('Raw Data'!A15<>"",AVERAGE('Raw Data'!Z15,'Raw Data'!AB15,'Raw Data'!AD15,'Raw Data'!AF15,'Raw Data'!AH15),"") | M28: =IF('Raw Data'!A15<>"",AVERAGE('Raw Data'!AA15,'Raw Data'!AC15,'Raw Data'!AE15,'Raw Data'!AG15,'Raw Data'!AI15),"") | N28: =IF(L28<>"",L28-M28,"") | O28: =IF('Raw Data'!A15<>"",AVERAGE('Raw Data'!AJ15,'Raw Data'!AL15,'Raw Data'!AN15,'Raw Data'!AP15,'Raw Data'!AR15),"") | P28: =IF('Raw Data'!A15<>"",AVERAGE('Raw Data'!AK15,'Raw Data'!AM15,'Raw Data'!AO15,'Raw Data'!AQ15,'Raw Data'!AS15),"") | Q28: =IF(O28<>"",O28-P28,"") | R28: =IF('Raw Data'!A15<>"",AVERAGE('Raw Data'!AT15,'Raw Data'!AV15,'Raw Data'!AX15,'Raw Data'!AZ15,'Raw Data'!BB15),"") | S28: =IF('Raw Data'!A15<>"",AVERAGE('Raw Data'!AU15,'Raw Data'!AW15,'Raw Data'!AY15,'Raw Data'!BA15,'Raw Data'!BC15),"") | T28: =IF(R28<>"",R28-S28,"") | U28: =IF('Raw Data'!A15<>"",AVERAGE('Raw Data'!BD15,'Raw Data'!BF15,'Raw Data'!BH15,'Raw Data'!BJ15,'Raw Data'!BL15),"") | V28: =IF('Raw Data'!A15<>"",AVERAGE('Raw Data'!BE15,'Raw Data'!BG15,'Raw Data'!BI15,'Raw Data'!BK15,'Raw Data'!BM15),"") | W28: =IF(U28<>"",U28-V28,"") | X28: =IF(A28<>"",AVERAGE(F28,I28,L28,O28,R28,U28),"") | Y28: =IF(A28<>"",AVERAGE(G28,J28,M28,P28,S28,V28),"") | Z28: =IF(A28<>"",X28-Y28,"") | AA28: =IF(A28<>"",ROUND(MIN(100,100*((MAX(0,K28)*0.25)+(MAX(0,Q28)*0.20)+(MAX(0,W28)*0.20)+(MAX(0,H28)*0.15)+(MAX(0,N28)*0.10)+(MAX(0,T28)*0.10))/9),1),"") | AB28: =IF(A28<>"",MIN(1,(0.5*AA28/100)+(0.3*MAX(0,K28)/9)+(0.2*MAX(0,Q28)/9)),"")
... A516: =IF('Raw Data'!A503<>"",'Raw Data'!A503,"") | B516: =IF('Raw Data'!B503<>"",'Raw Data'!B503,"") | C516: =IF('Raw Data'!C503<>"",'Raw Data'!C503,"") | D516: =IF('Raw Data'!D503<>"",'Raw Data'!D503,"") | E516: =IF('Raw Data'!E503<>"",'Raw Data'!E503,"") | F516: =IF('Raw Data'!A503<>"",AVERAGE('Raw Data'!F503,'Raw Data'!H503,'Raw Data'!J503,'Raw Data'!L503,'Raw Data'!N503),"") | G516: =IF('Raw Data'!A503<>"",AVERAGE('Raw Data'!G503,'Raw Data'!I503,'Raw Data'!K503,'Raw Data'!M503,'Raw Data'!O503),"") | H516: =IF(F516<>"",F516-G516,"") | I516: =IF('Raw Data'!A503<>"",AVERAGE('Raw Data'!P503,'Raw Data'!R503,'Raw Data'!T503,'Raw Data'!V503,'Raw Data'!X503),"") | J516: =IF('Raw Data'!A503<>"",AVERAGE('Raw Data'!Q503,'Raw Data'!S503,'Raw Data'!U503,'Raw Data'!W503,'Raw Data'!Y503),"") | K516: =IF(I516<>"",I516-J516,"") | L516: =IF('Raw Data'!A503<>"",AVERAGE('Raw Data'!Z503,'Raw Data'!AB503,'Raw Data'!AD503,'Raw Data'!AF503,'Raw Data'!AH503),"") | M516: =IF('Raw Data'!A503<>"",AVERAGE('Raw Data'!AA503,'Raw Data'!AC503,'Raw Data'!AE503,'Raw Data'!AG503,'Raw Data'!AI503),"") | N516: =IF(L516<>"",L516-M516,"") | O516: =IF('Raw Data'!A503<>"",AVERAGE('Raw Data'!AJ503,'Raw Data'!AL503,'Raw Data'!AN503,'Raw Data'!AP503,'Raw Data'!AR503),"") | P516: =IF('Raw Data'!A503<>"",AVERAGE('Raw Data'!AK503,'Raw Data'!AM503,'Raw Data'!AO503,'Raw Data'!AQ503,'Raw Data'!AS503),"") | Q516: =IF(O516<>"",O516-P516,"") | R516: =IF('Raw Data'!A503<>"",AVERAGE('Raw Data'!AT503,'Raw Data'!AV503,'Raw Data'!AX503,'Raw Data'!AZ503,'Raw Data'!BB503),"") | S516: =IF('Raw Data'!A503<>"",AVERAGE('Raw Data'!AU503,'Raw Data'!AW503,'Raw Data'!AY503,'Raw Data'!BA503,'Raw Data'!BC503),"") | T516: =IF(R516<>"",R516-S516,"") | U516: =IF('Raw Data'!A503<>"",AVERAGE('Raw Data'!BD503,'Raw Data'!BF503,'Raw Data'!BH503,'Raw Data'!BJ503,'Raw Data'!BL503),"") | V516: =IF('Raw Data'!A503<>"",AVERAGE('Raw Data'!BE503,'Raw Data'!BG503,'Raw Data'!BI503,'Raw Data'!BK503,'Raw Data'!BM503),"") | W516: =IF(U516<>"",U516-V516,"") | X516: =IF(A516<>"",AVERAGE(F516,I516,L516,O516,R516,U516),"") | Y516: =IF(A516<>"",AVERAGE(G516,J516,M516,P516,S516,V516),"") | Z516: =IF(A516<>"",X516-Y516,"") | AA516: =IF(A516<>"",ROUND(MIN(100,100*((MAX(0,K516)*0.25)+(MAX(0,Q516)*0.20)+(MAX(0,W516)*0.20)+(MAX(0,H516)*0.15)+(MAX(0,N516)*0.10)+(MAX(0,T516)*0.10))/9),1),"") | AB516: =IF(A516<>"",MIN(1,(0.5*AA516/100)+(0.3*MAX(0,K516)/9)+(0.2*MAX(0,Q516)/9)),"")

Sheet Dashboard
A1: Employee Experience Gap Analysis & Retention Risk Assessment
A2: Executive Dashboard — Key Metrics • Visual Analysis • Department View
A4: Overall Experience Index | D4: Retention Risk Score | G4: Engagement Score | J4: Largest Gap | M4: Strongest Dimension | P4: Total Respondents
A5: =ROUND('Scoring Engine'!B11,1) | D5: =ROUND('Scoring Engine'!B12,1) | G5: =ROUND(('Scoring Engine'!E5+'Scoring Engine'!E6+'Scoring Engine'!E7+'Scoring Engine'!E8+'Scoring Engine'!E9+'Scoring Engine'!E10)/6,1) | J5: =INDEX('Scoring Engine'!A5:A10,MATCH(MAX('Scoring Engine'!D5:D10),'Scoring Engine'!D5:D10,0)) | M5: =INDEX('Scoring Engine'!A5:A10,MATCH(MAX('Scoring Engine'!E5:E10),'Scoring Engine'!E5:E10,0)) | P5: =COUNTA('Raw Data'!A4:A53)
A6: Weighted avg of 6 dimensions | D6: Higher = greater flight risk | G6: Avg health across dimensions | J6: Dimension needing attention | M6: Top-performing dimension | P6: Sample of 50
A8: 1 Experience Profile — Promise vs Actual
A9: Dimension | B9: Promise Avg | C9: Experience Avg
A10: Job Fit | B10: ='Scoring Engine'!B5 | C10: ='Scoring Engine'!C5
A11: Manager Effectiveness | B11: ='Scoring Engine'!B6 | C11: ='Scoring Engine'!C6
A12: Team Collaboration | B12: ='Scoring Engine'!B7 | C12: ='Scoring Engine'!C7
A13: Workplace Culture | B13: ='Scoring Engine'!B8 | C13: ='Scoring Engine'!C8
A14: Innovation & Empowerment | B14: ='Scoring Engine'!B9 | C14: ='Scoring Engine'!C9
A15: Rewards & Growth | B15: ='Scoring Engine'!B10 | C15: ='Scoring Engine'!C10
A17: 2 Gap Analysis Heat Map — All 30 Items by Dimension
A18: Dimension | B18: Item 1 | C18: Item 2 | D18: Item 3 | E18: Item 4 | F18: Item 5
A19: Job Fit | B19: =AVERAGE('Raw Data'!F4:F53)-AVERAGE('Raw Data'!G4:G53) | C19: =AVERAGE('Raw Data'!H4:H53)-AVERAGE('Raw Data'!I4:I53) | D19: =AVERAGE('Raw Data'!J4:J53)-AVERAGE('Raw Data'!K4:K53) | E19: =AVERAGE('Raw Data'!L4:L53)-AVERAGE('Raw Data'!M4:M53) | F19: =AVERAGE('Raw Data'!N4:N53)-AVERAGE('Raw Data'!O4:O53)
A20: Manager Effectiveness | B20: =AVERAGE('Raw Data'!P4:P53)-AVERAGE('Raw Data'!Q4:Q53) | C20: =AVERAGE('Raw Data'!R4:R53)-AVERAGE('Raw Data'!S4:S53) | D20: =AVERAGE('Raw Data'!T4:T53)-AVERAGE('Raw Data'!U4:U53) | E20: =AVERAGE('Raw Data'!V4:V53)-AVERAGE('Raw Data'!W4:W53) | F20: =AVERAGE('Raw Data'!X4:X53)-AVERAGE('Raw Data'!Y4:Y53)
A21: Team Collaboration | B21: =AVERAGE('Raw Data'!Z4:Z53)-AVERAGE('Raw Data'!AA4:AA53) | C21: =AVERAGE('Raw Data'!AB4:AB53)-AVERAGE('Raw Data'!AC4:AC53) | D21: =AVERAGE('Raw Data'!AD4:AD53)-AVERAGE('Raw Data'!AE4:AE53) | E21: =AVERAGE('Raw Data'!AF4:AF53)-AVERAGE('Raw Data'!AG4:AG53) | F21: =AVERAGE('Raw Data'!AH4:AH53)-AVERAGE('Raw Data'!AI4:AI53)
A22: Workplace Culture | B22: =AVERAGE('Raw Data'!AJ4:AJ53)-AVERAGE('Raw Data'!AK4:AK53) | C22: =AVERAGE('Raw Data'!AL4:AL53)-AVERAGE('Raw Data'!AM4:AM53) | D22: =AVERAGE('Raw Data'!AN4:AN53)-AVERAGE('Raw Data'!AO4:AO53) | E22: =AVERAGE('Raw Data'!AP4:AP53)-AVERAGE('Raw Data'!AQ4:AQ53) | F22: =AVERAGE('Raw Data'!AR4:AR53)-AVERAGE('Raw Data'!AS4:AS53)
A23: Innovation & Empowerment | B23: =AVERAGE('Raw Data'!AT4:AT53)-AVERAGE('Raw Data'!AU4:AU53) | C23: =AVERAGE('Raw Data'!AV4:AV53)-AVERAGE('Raw Data'!AW4:AW53) | D23: =AVERAGE('Raw Data'!AX4:AX53)-AVERAGE('Raw Data'!AY4:AY53) | E23: =AVERAGE('Raw Data'!AZ4:AZ53)-AVERAGE('Raw Data'!BA4:BA53) | F23: =AVERAGE('Raw Data'!BB4:BB53)-AVERAGE('Raw Data'!BC4:BC53)
A24: Rewards & Growth | B24: =AVERAGE('Raw Data'!BD4:BD53)-AVERAGE('Raw Data'!BE4:BE53) | C24: =AVERAGE('Raw Data'!BF4:BF53)-AVERAGE('Raw Data'!BG4:BG53) | D24: =AVERAGE('Raw Data'!BH4:BH53)-AVERAGE('Raw Data'!BI4:BI53) | E24: =AVERAGE('Raw Data'!BJ4:BJ53)-AVERAGE('Raw Data'!BK4:BK53) | F24: =AVERAGE('Raw Data'!BL4:BL53)-AVERAGE('Raw Data'!BM4:BM53)
A25: < 1.0 Healthy | 1.0 - 2.0 Watch | 2.0 - 3.0 Concern | > 3.0 High Risk
A27: 3 Risk Matrix — Gap vs Importance by Dimension
A28: Dimension | B28: Gap Size | C28: Weight | D28: Risk Score
A29: Job Fit | B29: ='Scoring Engine'!D5 | C29: 0.2 | D29: =B29*C29*100 | E29: 20 | F29: =A29
A30: Manager Effectiveness | B30: ='Scoring Engine'!D6 | C30: 0.2 | D30: =B30*C30*100 | E30: 20 | F30: =A30
A31: Team Collaboration | B31: ='Scoring Engine'!D7 | C31: 0.15 | D31: =B31*C31*100 | E31: 15 | F31: =A31
A32: Workplace Culture | B32: ='Scoring Engine'!D8 | C32: 0.15 | D32: =B32*C32*100 | E32: 15 | F32: =A32
A33: Innovation & Empowerment | B33: ='Scoring Engine'!D9 | C33: 0.15 | D33: =B33*C33*100 | E33: 15 | F33: =A33
A34: Rewards & Growth | B34: ='Scoring Engine'!D10 | C34: 0.15 | D34: =B34*C34*100 | E34: 15 | F34: =A34
A44: 4 Department Comparison — Filterable Dimension Scores
A45: Filter: Department | B45: All
A47: Dimension | B47: Avg Promise | C47: Avg Experience | D47: Gap | E47: Health Score
A48: Job Fit | B48: =(IF($B$45="All",AVERAGE('Raw Data'!F$4:F$53),AVERAGEIF('Raw Data'!$B$4:$B$53,$B$45,'Raw Data'!F$4:F$53))+IF($B$45="All",AVERAGE('Raw Data'!H$4:H$53),AVERAGEIF('Raw Data'!$B$4:$B$53,$B$45,'Raw Data'!H$4:H$53))+IF($B$45="All",AVERAGE('Raw Data'!J$4:J$53),AVERAGEIF('Raw Data'!$B$4:$B$53,$B$45,'Raw Data'!J$4:J$53))+IF($B$45="All",AVERAGE('Raw Data'!L$4:L$53),AVERAGEIF('Raw Data'!$B$4:$B$53,$B$45,'Raw Data'!L$4:L$53))+IF($B$45="All",AVERAGE('Raw Data'!N$4:N$53),AVERAGEIF('Raw Data'!$B$4:$B$53,$B$45,'Raw Data'!N$4:N$53)))/5 | C48: =(IF($B$45="All",AVERAGE('Raw Data'!G$4:G$53),AVERAGEIF('Raw Data'!$B$4:$B$53,$B$45,'Raw Data'!G$4:G$53))+IF($B$45="All",AVERAGE('Raw Data'!I$4:I$53),AVERAGEIF('Raw Data'!$B$4:$B$53,$B$45,'Raw Data'!I$4:I$53))+IF($B$45="All",AVERAGE('Raw Data'!K$4:K$53),AVERAGEIF('Raw Data'!$B$4:$B$53,$B$45,'Raw Data'!K$4:K$53))+IF($B$45="All",AVERAGE('Raw Data'!M$4:M$53),AVERAGEIF('Raw Data'!$B$4:$B$53,$B$45,'Raw Data'!M$4:M$53))+IF($B$45="All",AVERAGE('Raw Data'!O$4:O$53),AVERAGEIF('Raw Data'!$B$4:$B$53,$B$45,'Raw Data'!O$4:O$53)))/5 | D48: =B48-C48 | E48: =MAX(0,MIN(100,100-D48*20))
A49: Manager Effectiveness | B49: =(IF($B$45="All",AVERAGE('Raw Data'!P$4:P$53),AVERAGEIF('Raw Data'!$B$4:$B$53,$B$45,'Raw Data'!P$4:P$53))+IF($B$45="All",AVERAGE('Raw Data'!R$4:R$53),AVERAGEIF('Raw Data'!$B$4:$B$53,$B$45,'Raw Data'!R$4:R$53))+IF($B$45="All",AVERAGE('Raw Data'!T$4:T$53),AVERAGEIF('Raw Data'!$B$4:$B$53,$B$45,'Raw Data'!T$4:T$53))+IF($B$45="All",AVERAGE('Raw Data'!V$4:V$53),AVERAGEIF('Raw Data'!$B$4:$B$53,$B$45,'Raw Data'!V$4:V$53))+IF($B$45="All",AVERAGE('Raw Data'!X$4:X$53),AVERAGEIF('Raw Data'!$B$4:$B$53,$B$45,'Raw Data'!X$4:X$53)))/5 | C49: =(IF($B$45="All",AVERAGE('Raw Data'!Q$4:Q$53),AVERAGEIF('Raw Data'!$B$4:$B$53,$B$45,'Raw Data'!Q$4:Q$53))+IF($B$45="All",AVERAGE('Raw Data'!S$4:S$53),AVERAGEIF('Raw Data'!$B$4:$B$53,$B$45,'Raw Data'!S$4:S$53))+IF($B$45="All",AVERAGE('Raw Data'!U$4:U$53),AVERAGEIF('Raw Data'!$B$4:$B$53,$B$45,'Raw Data'!U$4:U$53))+IF($B$45="All",AVERAGE('Raw Data'!W$4:W$53),AVERAGEIF('Raw Data'!$B$4:$B$53,$B$45,'Raw Data'!W$4:W$53))+IF($B$45="All",AVERAGE('Raw Data'!Y$4:Y$53),AVERAGEIF('Raw Data'!$B$4:$B$53,$B$45,'Raw Data'!Y$4:Y$53)))/5 | D49: =B49-C49 | E49: =MAX(0,MIN(100,100-D49*20))
A50: Team Collaboration | B50: =(IF($B$45="All",AVERAGE('Raw Data'!Z$4:Z$53),AVERAGEIF('Raw Data'!$B$4:$B$53,$B$45,'Raw Data'!Z$4:Z$53))+IF($B$45="All",AVERAGE('Raw Data'!AB$4:AB$53),AVERAGEIF('Raw Data'!$B$4:$B$53,$B$45,'Raw Data'!AB$4:AB$53))+IF($B$45="All",AVERAGE('Raw Data'!AD$4:AD$53),AVERAGEIF('Raw Data'!$B$4:$B$53,$B$45,'Raw Data'!AD$4:AD$53))+IF($B$45="All",AVERAGE('Raw Data'!AF$4:AF$53),AVERAGEIF('Raw Data'!$B$4:$B$53,$B$45,'Raw Data'!AF$4:AF$53))+IF($B$45="All",AVERAGE('Raw Data'!AH$4:AH$53),AVERAGEIF('Raw Data'!$B$4:$B$53,$B$45,'Raw Data'!AH$4:AH$53)))/5 | C50: =(IF($B$45="All",AVERAGE('Raw Data'!AA$4:AA$53),AVERAGEIF('Raw Data'!$B$4:$B$53,$B$45,'Raw Data'!AA$4:AA$53))+IF($B$45="All",AVERAGE('Raw Data'!AC$4:AC$53),AVERAGEIF('Raw Data'!$B$4:$B$53,$B$45,'Raw Data'!AC$4:AC$53))+IF($B$45="All",AVERAGE('Raw Data'!AE$4:AE$53),AVERAGEIF('Raw Data'!$B$4:$B$53,$B$45,'Raw Data'!AE$4:AE$53))+IF($B$45="All",AVERAGE('Raw Data'!AG$4:AG$53),AVERAGEIF('Raw Data'!$B$4:$B$53,$B$45,'Raw Data'!AG$4:AG$53))+IF($B$45="All",AVERAGE('Raw Data'!AI$4:AI$53),AVERAGEIF('Raw Data'!$B$4:$B$53,$B$45,'Raw Data'!AI$4:AI$53)))/5 | D50: =B50-C50 | E50: =MAX(0,MIN(100,100-D50*20))
A51: Workplace Culture | B51: =(IF($B$45="All",AVERAGE('Raw Data'!AJ$4:AJ$53),AVERAGEIF('Raw Data'!$B$4:$B$53,$B$45,'Raw Data'!AJ$4:AJ$53))+IF($B$45="All",AVERAGE('Raw Data'!AL$4:AL$53),AVERAGEIF('Raw Data'!$B$4:$B$53,$B$45,'Raw Data'!AL$4:AL$53))+IF($B$45="All",AVERAGE('Raw Data'!AN$4:AN$53),AVERAGEIF('Raw Data'!$B$4:$B$53,$B$45,'Raw Data'!AN$4:AN$53))+IF($B$45="All",AVERAGE('Raw Data'!AP$4:AP$53),AVERAGEIF('Raw Data'!$B$4:$B$53,$B$45,'Raw Data'!AP$4:AP$53))+IF($B$45="All",AVERAGE('Raw Data'!AR$4:AR$53),AVERAGEIF('Raw Data'!$B$4:$B$53,$B$45,'Raw Data'!AR$4:AR$53)))/5 | C51: =(IF($B$45="All",AVERAGE('Raw Data'!AK$4:AK$53),AVERAGEIF('Raw Data'!$B$4:$B$53,$B$45,'Raw Data'!AK$4:AK$53))+IF($B$45="All",AVERAGE('Raw Data'!AM$4:AM$53),AVERAGEIF('Raw Data'!$B$4:$B$53,$B$45,'Raw Data'!AM$4:AM$53))+IF($B$45="All",AVERAGE('Raw Data'!AO$4:AO$53),AVERAGEIF('Raw Data'!$B$4:$B$53,$B$45,'Raw Data'!AO$4:AO$53))+IF($B$45="All",AVERAGE('Raw Data'!AQ$4:AQ$53),AVERAGEIF('Raw Data'!$B$4:$B$53,$B$45,'Raw Data'!AQ$4:AQ$53))+IF($B$45="All",AVERAGE('Raw Data'!AS$4:AS$53),AVERAGEIF('Raw Data'!$B$4:$B$53,$B$45,'Raw Data'!AS$4:AS$53)))/5 | D51: =B51-C51 | E51: =MAX(0,MIN(100,100-D51*20))
A52: Innovation & Empowerment | B52: =(IF($B$45="All",AVERAGE('Raw Data'!AT$4:AT$53),AVERAGEIF('Raw Data'!$B$4:$B$53,$B$45,'Raw Data'!AT$4:AT$53))+IF($B$45="All",AVERAGE('Raw Data'!AV$4:AV$53),AVERAGEIF('Raw Data'!$B$4:$B$53,$B$45,'Raw Data'!AV$4:AV$53))+IF($B$45="All",AVERAGE('Raw Data'!AX$4:AX$53),AVERAGEIF('Raw Data'!$B$4:$B$53,$B$45,'Raw Data'!AX$4:AX$53))+IF($B$45="All",AVERAGE('Raw Data'!AZ$4:AZ$53),AVERAGEIF('Raw Data'!$B$4:$B$53,$B$45,'Raw Data'!AZ$4:AZ$53))+IF($B$45="All",AVERAGE('Raw Data'!BB$4:BB$53),AVERAGEIF('Raw Data'!$B$4:$B$53,$B$45,'Raw Data'!BB$4:BB$53)))/5 | C52: =(IF($B$45="All",AVERAGE('Raw Data'!AU$4:AU$53),AVERAGEIF('Raw Data'!$B$4:$B$53,$B$45,'Raw Data'!AU$4:AU$53))+IF($B$45="All",AVERAGE('Raw Data'!AW$4:AW$53),AVERAGEIF('Raw Data'!$B$4:$B$53,$B$45,'Raw Data'!AW$4:AW$53))+IF($B$45="All",AVERAGE('Raw Data'!AY$4:AY$53),AVERAGEIF('Raw Data'!$B$4:$B$53,$B$45,'Raw Data'!AY$4:AY$53))+IF($B$45="All",AVERAGE('Raw Data'!BA$4:BA$53),AVERAGEIF('Raw Data'!$B$4:$B$53,$B$45,'Raw Data'!BA$4:BA$53))+IF($B$45="All",AVERAGE('Raw Data'!BC$4:BC$53),AVERAGEIF('Raw Data'!$B$4:$B$53,$B$45,'Raw Data'!BC$4:BC$53)))/5 | D52: =B52-C52 | E52: =MAX(0,MIN(100,100-D52*20))
A53: Rewards & Growth | B53: =(IF($B$45="All",AVERAGE('Raw Data'!BD$4:BD$53),AVERAGEIF('Raw Data'!$B$4:$B$53,$B$45,'Raw Data'!BD$4:BD$53))+IF($B$45="All",AVERAGE('Raw Data'!BF$4:BF$53),AVERAGEIF('Raw Data'!$B$4:$B$53,$B$45,'Raw Data'!BF$4:BF$53))+IF($B$45="All",AVERAGE('Raw Data'!BH$4:BH$53),AVERAGEIF('Raw Data'!$B$4:$B$53,$B$45,'Raw Data'!BH$4:BH$53))+IF($B$45="All",AVERAGE('Raw Data'!BJ$4:BJ$53),AVERAGEIF('Raw Data'!$B$4:$B$53,$B$45,'Raw Data'!BJ$4:BJ$53))+IF($B$45="All",AVERAGE('Raw Data'!BL$4:BL$53),AVERAGEIF('Raw Data'!$B$4:$B$53,$B$45,'Raw Data'!BL$4:BL$53)))/5 | C53: =(IF($B$45="All",AVERAGE('Raw Data'!BE$4:BE$53),AVERAGEIF('Raw Data'!$B$4:$B$53,$B$45,'Raw Data'!BE$4:BE$53))+IF($B$45="All",AVERAGE('Raw Data'!BG$4:BG$53),AVERAGEIF('Raw Data'!$B$4:$B$53,$B$45,'Raw Data'!BG$4:BG$53))+IF($B$45="All",AVERAGE('Raw Data'!BI$4:BI$53),AVERAGEIF('Raw Data'!$B$4:$B$53,$B$45,'Raw Data'!BI$4:BI$53))+IF($B$45="All",AVERAGE('Raw Data'!BK$4:BK$53),AVERAGEIF('Raw Data'!$B$4:$B$53,$B$45,'Raw Data'!BK$4:BK$53))+IF($B$45="All",AVERAGE('Raw Data'!BM$4:BM$53),AVERAGEIF('Raw Data'!$B$4:$B$53,$B$45,'Raw Data'!BM$4:BM$53)))/5 | D53: =B53-C53 | E53: =MAX(0,MIN(100,100-D53*20))

Sheet Reliability Analysis
A1: Cronbach's Alpha -- Internal Consistency Reliability
A2: Target: alpha >= 0.70. All calculations use VAR (sample variance) and native Excel formulas.
A4: Dimension | B4: # Items (k) | C4: Sum Item Variances | D4: Total Score Variance | E4: Cronbach's alpha | F4: Interpretation
A5: Job Fit | B5: 5 | C5: =SUM(VAR('Raw Data'!G4:G53),VAR('Raw Data'!I4:I53),VAR('Raw Data'!K4:K53),VAR('Raw Data'!M4:M53),VAR('Raw Data'!O4:O53)) | D5: =VAR(G105:G154) | E5: =(B5/(B5-1))*(1-C5/D5) | F5: =IF(E5>=0.9,"Excellent",IF(E5>=0.8,"Good",IF(E5>=0.7,"Acceptable",IF(E5>=0.6,"Questionable",IF(E5>=0.5,"Poor","Unacceptable")))))
A6: Manager Effectiveness | B6: 5 | C6: =SUM(VAR('Raw Data'!Q4:Q53),VAR('Raw Data'!S4:S53),VAR('Raw Data'!U4:U53),VAR('Raw Data'!W4:W53),VAR('Raw Data'!Y4:Y53)) | D6: =VAR(G155:G204) | E6: =(B6/(B6-1))*(1-C6/D6) | F6: =IF(E6>=0.9,"Excellent",IF(E6>=0.8,"Good",IF(E6>=0.7,"Acceptable",IF(E6>=0.6,"Questionable",IF(E6>=0.5,"Poor","Unacceptable")))))
A7: Team Collaboration | B7: 5 | C7: =SUM(VAR('Raw Data'!AA4:AA53),VAR('Raw Data'!AC4:AC53),VAR('Raw Data'!AE4:AE53),VAR('Raw Data'!AG4:AG53),VAR('Raw Data'!AI4:AI53)) | D7: =VAR(G205:G254) | E7: =(B7/(B7-1))*(1-C7/D7) | F7: =IF(E7>=0.9,"Excellent",IF(E7>=0.8,"Good",IF(E7>=0.7,"Acceptable",IF(E7>=0.6,"Questionable",IF(E7>=0.5,"Poor","Unacceptable")))))
A8: Workplace Culture | B8: 5 | C8: =SUM(VAR('Raw Data'!AK4:AK53),VAR('Raw Data'!AM4:AM53),VAR('Raw Data'!AO4:AO53),VAR('Raw Data'!AQ4:AQ53),VAR('Raw Data'!AS4:AS53)) | D8: =VAR(G255:G304) | E8: =(B8/(B8-1))*(1-C8/D8) | F8: =IF(E8>=0.9,"Excellent",IF(E8>=0.8,"Good",IF(E8>=0.7,"Acceptable",IF(E8>=0.6,"Questionable",IF(E8>=0.5,"Poor","Unacceptable")))))
A9: Innovation & Empowerment | B9: 5 | C9: =SUM(VAR('Raw Data'!AU4:AU53),VAR('Raw Data'!AW4:AW53),VAR('Raw Data'!AY4:AY53),VAR('Raw Data'!BA4:BA53),VAR('Raw Data'!BC4:BC53)) | D9: =VAR(G305:G354) | E9: =(B9/(B9-1))*(1-C9/D9) | F9: =IF(E9>=0.9,"Excellent",IF(E9>=0.8,"Good",IF(E9>=0.7,"Acceptable",IF(E9>=0.6,"Questionable",IF(E9>=0.5,"Poor","Unacceptable")))))
A10: Rewards & Growth | B10: 5 | C10: =SUM(VAR('Raw Data'!BE4:BE53),VAR('Raw Data'!BG4:BG53),VAR('Raw Data'!BI4:BI53),VAR('Raw Data'!BK4:BK53),VAR('Raw Data'!BM4:BM53)) | D10: =VAR(G355:G404) | E10: =(B10/(B10-1))*(1-C10/D10) | F10: =IF(E10>=0.9,"Excellent",IF(E10>=0.8,"Good",IF(E10>=0.7,"Acceptable",IF(E10>=0.6,"Questionable",IF(E10>=0.5,"Poor","Unacceptable")))))
A12: Cronbach's Alpha measures internal consistency: how closely related the items are as a group. alpha >= 0.70 is the research standard for acceptable reliability.
G105: =SUM('Raw Data'!G4+'Raw Data'!I4+'Raw Data'!K4+'Raw Data'!M4+'Raw Data'!O4)
G106: =SUM('Raw Data'!G5+'Raw Data'!I5+'Raw Data'!K5+'Raw Data'!M5+'Raw Data'!O5)
